Workbook

Sheet readme
A1: README
A3: 20230303 Okayasu 修正
A4: 20230221 Okayasu 修正
A5: 20230220 Okayasu 修正
A6: 20230219 Okayasu
A8: * 更新履歴
A9: 20230303 : injector_lattice_20230303.xlsx
A10: fy_r0_02，SY2 の 4 台の磁場特性 (ボア径・有効磁場長) については，紙谷氏回答待ち．
A11: 従来ファイル名を injector_lattice_file_(survey_data_year)_(revice_id) としていたが，由元氏の依頼により命名ルールを変更．
A12: SY2 の計 4 台の偏向電磁石 : bm_dc_1, 2, 3, 4 の設計座標 (x) を修正．
A13: ファイル名を injector_lattice_(修正日)_revise#.xlsx の命名規則に変更．
A14: "lattice_file" シート名を "lattice" に変更．
... A87: M 列 : Bore dia/DA [mm] 電磁石の場合は Linac_Magnet_parameters_20210910.xlsx から拾ったボア直径．
B88: 真空機器の場合はチェンバーまで拾うと数が膨大になるため，コリメータ・ビームストッパのみ (可動) 代表値を入れた．
A89: N 列 : 空欄
A90: O 列 : 備考．
A92: 4. 測地線補正
A93: 測地線曲線の三次関数の係数算出．
A94: 3 ~ 24 行は A セクター先頭から B セクター終端までの PD センサーの座標．N$3 ~ Q$3 までの係数を参照．
A95: 26 ~ 105 行は C セクター先頭から 5 セクター終端までの PD センサーの座標．N$26 ~ Q$26 までの係数を参照．
A96: 多項式の係数参照先は "lattice_file" シートの R 列．
A98: 5. survey_data
A99: 測量データの SA (Spatial Analayzer) 出力．
A100: 内訳は point name, x, y, z, Ux, Uy, Uz．単位は全て mm．Ux ~ Uz は網計算後の各測量点の誤差．
A102: 6. lattice_file
A103: A ~ G 列は "設計座標" シートと共通．
... A105: K, L, M, N 列 : x, y, z の測量座標 (srveyed coordinates)．識別用に suffix "s" を付した．
B106: ys に関しては設計座標と同値．
B107: 尚，M 列の zs はリフレクタ中心の水準で，光学計算では利用度が少ないと判断し，フォントをグレーにした．
B108: N 列の zs' は機器中心水準に測地線補正を勘案したもの．光学計算で活用されたし．
A109: O, P, Q, R 列 : 測量座標と設計座標の差分．水準に関しては機器中心である R 列の値を参照すべし．
B110: 尚，測量していない電磁石以外の座標については，最初に Δx, Δz を隣接する電磁石から線形補間で算出し，x, z を求めた．
A111: S, T, U 列 : 右上図で定義した機器の傾き誤差．
B112: 但し A1/AS の機器に関しては測量を実施していないため，全ての傾き誤差を 0 とした．
A113: V 列 : Length [mm] 電磁石の場合は Linac_Magnet_Parameters_20210910.xlsx から拾った磁極長長さ．真空機器の場合はコリメータ・ビームストッパの長さ．
A114: W 列 : Bore dia/DA [mm] 電磁石の場合は Linac_Magnet_parameters_20210910.xlsx から拾ったボア直径．
B115: 真空機器の場合はチェンバーまで拾うと数が膨大になるため，コリメータ・ビームストッパのみ (可動) 代表値を入れた．
A116: X 列 : 空欄
A117: Y 列 : 備考．

Sheet magnet_list
A1: 電磁石名称 | B1: 電源名称 | C1: 情報更新日 | D1: 情報更新者 | E1: 電磁石形式 | F1: 所属ビームライン名 | G1: ビームライン座標値 | H1: 製造者 | I1: 製造年月 | J1: 設置年月 | K1: 型番/製造番号 | L1: ボア直径/磁極間距離 [mm] | M1: 磁極長 [mm] | N1: 最大電流 [A] | O1: ヨーク部外径 [mm] | P1: 最大電圧 [V] | Q1: コイル巻数 [turn/coil] | R1: コイル導線径 [mm] | S1: コイル導線断面積 [mm^2] | T1: インダクタンス [mH] | U1: コイル抵抗値 [Ohm/Magnet] | V1: 磁場特性 (最大) | W1: 冷却方式 | X1: 冷却水量 [L/min] | Y1: 重量 [kg] | Z1: Component ID | AA1: 物品管理番号 | AB1: Remarks | AC1: 予備1 | AD1: 予備2 | AE1: 予備3 | AF1: 予備4 | AG1: 予備5 | AH1: 励磁特性データ代表名 | AI1: ヒステリシスループの向き | AJ1: 磁場有効長 | AK1: 電流の区間数 | AL1: 区間最小電流 | AM1: 区間最大電流 | AN1: 多項式係数BL0 | AO1: BL1 | AP1: BL2 | AQ1: BL3 | AR1: BL4 | AS1: BL5 | AT1: BL6 | AU1: BL7 | AV1: BL8 | AW1: BL9
A2: ML_AT_G0 | B2: ML_AT_G0 | C2: 2021/09/10 | D2: 紙谷 | E2: マグネティックレンズ | M2: 60 | N2: 3 | Q2: 1361 | V2: 0.20715 | AH2: ML_AT_G0 | AJ2: 0.02473 | AK2: 1 | AL2: 0 | AM2: 3 | AN2: 0 | AO2: 0.001708843 | AP2: 0 | AQ2: 0 | AR2: 0 | AS2: 0 | AT2: 0 | AU2: 0 | AV2: 0 | AW2: 0
A3: SX_AT_G0 | B3: SX_AT_G0 | C3: 2021/09/10 | D3: 紙谷 | E3: 空芯ステアリングコイル | J3: 2015.05 | L3: 74 | M3: 65 | N3: 3 | P3: 1.6 | Q3: 45 | U3: 0.54166667 | V3: 0.001428 | W3: air | AB3: ターン数は概算値 | AH3: SX_AT_G0 | AJ3: 0.05796 | AK3: 1 | AL3: -3 | AM3: 3 | AN3: 0 | AO3: 2.758896e-05 | AP3: 0 | AQ3: 0 | AR3: 0 | AS3: 0 | AT3: 0 | AU3: 0 | AV3: 0 | AW3: 0
A4: SY_AT_G0 | B4: SY_AT_G0 | C4: 2021/09/10 | D4: 紙谷 | E4: 空芯ステアリングコイル | J4: 2015.05 | L4: 74 | M4: 65 | N4: 3 | P4: 1.6 | Q4: 45 | U4: 0.54166667 | V4: 0.001428 | W4: air | AB4: ターン数は概算値 | AH4: SX_AT_G0 | AJ4: 0.05796 | AK4: 1 | AL4: -3 | AM4: 3 | AN4: 0 | AO4: 2.758896e-05 | AP4: 0 | AQ4: 0 | AR4: 0 | AS4: 0 | AT4: 0 | AU4: 0 | AV4: 0 | AW4: 0
A5: ML_AT_G1 | B5: ML_AT_G1 | C5: 2021/09/10 | D5: 紙谷 | E5: マグネティックレンズ | M5: 60 | N5: 3 | Q5: 1361 | V5: 0.20715 | AH5: ML_AT_G0 | AJ5: 0.02473 | AK5: 1 | AL5: 0 | AM5: 3 | AN5: 0 | AO5: 0.001708843 | AP5: 0 | AQ5: 0 | AR5: 0 | AS5: 0 | AT5: 0 | AU5: 0 | AV5: 0 | AW5: 0
A6: SX_AT_G1 | B6: SX_AT_G1 | C6: 2021/09/10 | D6: 紙谷 | E6: 空芯ステアリングコイル | J6: 2015.05 | L6: 40 | M6: 40 | N6: 3 | P6: 4.8 | Q6: 66 | U6: 1.5923333 | V6: 0.0034 | W6: air | AB6: ターン数は概算値 | AH6: SX_AT_G1 | AJ6: 0.04196 | AK6: 1 | AL6: -3 | AM6: 3 | AN6: 0 | AO6: 4.7554667e-05 | AP6: 0 | AQ6: 0 | AR6: 0 | AS6: 0 | AT6: 0 | AU6: 0 | AV6: 0 | AW6: 0
A7: SY_AT_G1 | B7: SY_AT_G1 | C7: 2021/09/10 | D7: 紙谷 | E7: 空芯ステアリングコイル | J7: 2015.05 | L7: 40 | M7: 40 | N7: 3 | P7: 4.8 | Q7: 66 | U7: 1.5923333 | V7: 0.0034 | W7: air | AB7: ターン数は概算値 | AH7: SX_AT_G1 | AJ7: 0.04196 | AK7: 1 | AL7: -3 | AM7: 3 | AN7: 0 | AO7: 4.7554667e-05 | AP7: 0 | AQ7: 0 | AR7: 0 | AS7: 0 | AT7: 0 | AU7: 0 | AV7: 0 | AW7: 0
A8: SL_AT_G1 | B8: SL_AT_G1 | C8: 2021/09/10 | D8: 紙谷 | E8: ヘルムホルツコイル | H8: TOKIN | AH8: SL_AT_G1 | AJ8: 0.29026695 | AK8: 1 | AL8: 0 | AM8: 35 | AN8: 0 | AO8: 0.00077925926 | AP8: 0 | AQ8: 0 | AR8: 0 | AS8: 0 | AT8: 0 | AU8: 0 | AV8: 0 | AW8: 0
A9: SL_AT_G2 | B9: SL_AT_G2 | C9: 2021/09/10 | D9: 紙谷 | E9: ヘルムホルツコイル | H9: TOKIN | AH9: SL_AT_G1 | AJ9: 0.29026695 | AK9: 1 | AL9: 0 | AM9: 35 | AN9: 0 | AO9: 0.00077925926 | AP9: 0 | AQ9: 0 | AR9: 0 | AS9: 0 | AT9: 0 | AU9: 0 | AV9: 0 | AW9: 0
A10: SL_AT_G3 | B10: SL_AT_G3/4 | C10: 2021/09/10 | D10: 紙谷 | E10: ヘルムホルツコイル | H10: TOKIN | AH10: SL_AT_G1 | AJ10: 0.29026695 | AK10: 1 | AL10: 0 | AM10: 35 | AN10: 0 | AO10: 0.00077925926 | AP10: 0 | AQ10: 0 | AR10: 0 | AS10: 0 | AT10: 0 | AU10: 0 | AV10: 0 | AW10: 0
A11: SL_AT_G4 | B11: SL_AT_G3/4 | C11: 2021/09/10 | D11: 紙谷 | E11: ヘルムホルツコイル | H11: TOKIN | AH11: SL_AT_G1 | AJ11: 0.29026695 | AK11: 1 | AL11: 0 | AM11: 35 | AN11: 0 | AO11: 0.00077925926 | AP11: 0 | AQ11: 0 | AR11: 0 | AS11: 0 | AT11: 0 | AU11: 0 | AV11: 0 | AW11: 0
A12: SX_AT_G4 | B12: SX_AT_G4 | C12: 2021/09/10 | D12: 紙谷 | E12: 空芯ステアリングコイル | J12: 2015.05 | L12: 76 | M12: 125 | N12: 5 | P12: 5.9 | Q12: 96 | V12: 0.00433 | W12: air | AB12: ターン数は概算値 | AH12: SX_AT_G4 | AJ12: 0.09973 | AK12: 1 | AL12: -5 | AM12: 5 | AN12: 0 | AO12: 8.636618e-05 | AP12: 0 | AQ12: 0 | AR12: 0 | AS12: 0 | AT12: 0 | AU12: 0 | AV12: 0 | AW12: 0
A13: SY_AT_G4 | B13: SY_AT_G4 | C13: 2021/09/10 | D13: 紙谷 | E13: 空芯ステアリングコイル | J13: 2015.05 | L13: 76 | M13: 125 | N13: 5 | P13: 5.9 | Q13: 96 | V13: 0.00433 | W13: air | AB13: ターン数は概算値 | AH13: SX_AT_G4 | AJ13: 0.09973 | AK13: 1 | AL13: -5 | AM13: 5 | AN13: 0 | AO13: 8.636618e-05 | AP13: 0 | AQ13: 0 | AR13: 0 | AS13: 0 | AT13: 0 | AU13: 0 | AV13: 0 | AW13: 0
A14: SL_AT_G5 | B14: SL_AT_G5/6 | C14: 2021/09/10 | D14: 紙谷 | E14: ヘルムホルツコイル | H14: TOKIN | AH14: SL_AT_G1 | AJ14: 0.29026695 | AK14: 1 | AL14: 0 | AM14: 35 | AN14: 0 | AO14: 0.00077925926 | AP14: 0 | AQ14: 0 | AR14: 0 | AS14: 0 | AT14: 0 | AU14: 0 | AV14: 0 | AW14: 0
A15: SL_AT_G6 | B15: SL_AT_G5/6 | C15: 2021/09/10 | D15: 紙谷 | E15: ヘルムホルツコイル | H15: TOKIN | AH15: SL_AT_G1 | AJ15: 0.29026695 | AK15: 1 | AL15: 0 | AM15: 35 | AN15: 0 | AO15: 0.00077925926 | AP15: 0 | AQ15: 0 | AR15: 0 | AS15: 0 | AT15: 0 | AU15: 0 | AV15: 0 | AW15: 0
A16: SL_AT_S1 | B16: SL_AT_S1/2 | C16: 2021/09/10 | D16: 紙谷 | E16: ヘルムホルツコイル | H16: TOKIN | AH16: SL_AT_G1 | AJ16: 0.29026695 | AK16: 1 | AL16: 0 | AM16: 35 | AN16: 0 | AO16: 0.00077925926 | AP16: 0 | AQ16: 0 | AR16: 0 | AS16: 0 | AT16: 0 | AU16: 0 | AV16: 0 | AW16: 0
A17: SL_AT_S2 | B17: SL_AT_S1/2 | C17: 2021/09/10 | D17: 紙谷 | E17: ヘルムホルツコイル | H17: TOKIN | AH17: SL_AT_G1 | AJ17: 0.29026695 | AK17: 1 | AL17: 0 | AM17: 35 | AN17: 0 | AO17: 0.00077925926 | AP17: 0 | AQ17: 0 | AR17: 0 | AS17: 0 | AT17: 0 | AU17: 0 | AV17: 0 | AW17: 0
A18: SL_AT_S3 | B18: SL_AT_S3/4 | C18: 2021/09/10 | D18: 紙谷 | E18: ヘルムホルツコイル | H18: TOKIN | AH18: SL_AT_G1 | AJ18: 0.29026695 | AK18: 1 | AL18: 0 | AM18: 35 | AN18: 0 | AO18: 0.00077925926 | AP18: 0 | AQ18: 0 | AR18: 0 | AS18: 0 | AT18: 0 | AU18: 0 | AV18: 0 | AW18: 0
A19: SL_AT_S4 | B19: SL_AT_S3/4 | C19: 2021/09/10 | D19: 紙谷 | E19: ヘルムホルツコイル | H19: TOKIN | AH19: SL_AT_G1 | AJ19: 0.29026695 | AK19: 1 | AL19: 0 | AM19: 35 | AN19: 0 | AO19: 0.00077925926 | AP19: 0 | AQ19: 0 | AR19: 0 | AS19: 0 | AT19: 0 | AU19: 0 | AV19: 0 | AW19: 0
A20: SL_AT_S5 | B20: SL_AT_S5/6 | C20: 2021/09/10 | D20: 紙谷 | E20: ヘルムホルツコイル | H20: TOKIN | AH20: SL_AT_G1 | AJ20: 0.29026695 | AK20: 1 | AL20: 0 | AM20: 35 | AN20: 0 | AO20: 0.00077925926 | AP20: 0 | AQ20: 0 | AR20: 0 | AS20: 0 | AT20: 0 | AU20: 0 | AV20: 0 | AW20: 0
A21: SL_AT_S6 | B21: SL_AT_S5/6 | C21: 2021/09/10 | D21: 紙谷 | E21: ヘルムホルツコイル | H21: TOKIN | AH21: SL_AT_G1 | AJ21: 0.29026695 | AK21: 1 | AL21: 0 | AM21: 35 | AN21: 0 | AO21: 0.00077925926 | AP21: 0 | AQ21: 0 | AR21: 0 | AS21: 0 | AT21: 0 | AU21: 0 | AV21: 0 | AW21: 0
A22: SX_AT_S6 | B22: SX_AT_S6 | C22: 2021/09/10 | D22: 紙谷 | E22: 空芯ステアリングコイル | J22: 2015.05 | L22: 76 | M22: 125 | N22: 5 | P22: 5.9 | Q22: 96 | V22: 0.00433 | W22: air | AB22: ターン数は概算値 | AH22: SX_AT_G4 | AJ22: 0.09973 | AK22: 1 | AL22: -5 | AM22: 5 | AN22: 0 | AO22: 8.636618e-05 | AP22: 0 | AQ22: 0 | AR22: 0 | AS22: 0 | AT22: 0 | AU22: 0 | AV22: 0 | AW22: 0
A23: SY_AT_S6 | B23: SY_AT_S6 | C23: 2021/09/10 | D23: 紙谷 | E23: 空芯ステアリングコイル | J23: 2015.05 | L23: 76 | M23: 125 | N23: 5 | P23: 5.9 | Q23: 96 | V23: 0.00433 | W23: air | AB23: ターン数は概算値 | AH23: SX_AT_G4 | AJ23: 0.09973 | AK23: 1 | AL23: -5 | AM23: 5 | AN23: 0 | AO23: 8.636618e-05 | AP23: 0 | AQ23: 0 | AR23: 0 | AS23: 0 | AT23: 0 | AU23: 0 | AV23: 0 | AW23: 0
A24: SL_AT_S7 | B24: SL_AT_S7/8 | C24: 2021/09/10 | D24: 紙谷 | E24: ヘルムホルツコイル | H24: TOKIN | AH24: SL_AT_G1 | AJ24: 0.29026695 | AK24: 1 | AL24: 0 | AM24: 35 | AN24: 0 | AO24: 0.00077925926 | AP24: 0 | AQ24: 0 | AR24: 0 | AS24: 0 | AT24: 0 | AU24: 0 | AV24: 0 | AW24: 0
A25: SL_AT_S8 | B25: SL_AT_S7/8 | C25: 2021/09/10 | D25: 紙谷 | E25: ヘルムホルツコイル | H25: TOKIN | AH25: SL_AT_G1 | AJ25: 0.29026695 | AK25: 1 | AL25: 0 | AM25: 35 | AN25: 0 | AO25: 0.00077925926 | AP25: 0 | AQ25: 0 | AR25: 0 | AS25: 0 | AT25: 0 | AU25: 0 | AV25: 0 | AW25: 0
A26: SL_AT_S9 | B26: SL_AT_S9 | C26: 2021/09/10 | D26: 紙谷 | E26: ヘルムホルツコイル | H26: TOKIN | AH26: SL_AT_S9 | AJ26: 0.3300766 | AK26: 1 | AL26: 0 | AM26: 35 | AN26: 0 | AO26: 0.00086337037 | AP26: 0 | AQ26: 0 | AR26: 0 | AS26: 0 | AT26: 0 | AU26: 0 | AV26: 0 | AW26: 0
A27: SL_AT_SA | B27: SL_AT_SA | C27: 2021/09/10 | D27: 紙谷 | E27: ヘルムホルツコイル | H27: TOKIN | AH27: SL_AT_S9 | AJ27: 0.3300766 | AK27: 1 | AL27: 0 | AM27: 35 | AN27: 0 | AO27: 0.00086337037 | AP27: 0 | AQ27: 0 | AR27: 0 | AS27: 0 | AT27: 0 | AU27: 0 | AV27: 0 | AW27: 0
A28: SL_AT_P | B28: SL_AT_P | C28: 2021/09/10 | D28: 紙谷 | E28: ヘルムホルツコイル | H28: TOKIN | AH28: SL_AT_S9 | AJ28: 0.3300766 | AK28: 1 | AL28: 0 | AM28: 35 | AN28: 0 | AO28: 0.00086337037 | AP28: 0 | AQ28: 0 | AR28: 0 | AS28: 0 | AT28: 0 | AU28: 0 | AV28: 0 | AW28: 0
A29: SL_AT_B1 | B29: SL_AT_B1 | C29: 2021/09/10 | D29: 紙谷 | E29: ヘルムホルツコイル | H29: TOKIN | AH29: SL_AT_G1 | AJ29: 0.29026695 | AK29: 1 | AL29: 0 | AM29: 35 | AN29: 0 | AO29: 0.00077925926 | AP29: 0 | AQ29: 0 | AR29: 0 | AS29: 0 | AT29: 0 | AU29: 0 | AV29: 0 | AW29: 0
A30: SL_AT_B2 | B30: SL_AT_B2/3 | C30: 2021/09/10 | D30: 紙谷 | E30: ヘルムホルツコイル | H30: TOKIN | AH30: SL_AT_G1 | AJ30: 0.29026695 | AK30: 1 | AL30: 0 | AM30: 35 | AN30: 0 | AO30: 0.00077925926 | AP30: 0 | AQ30: 0 | AR30: 0 | AS30: 0 | AT30: 0 | AU30: 0 | AV30: 0 | AW30: 0
A31: SL_AT_B3 | B31: SL_AT_B2/3 | C31: 2021/09/10 | D31: 紙谷 | E31: ヘルムホルツコイル | H31: TOKIN | AH31: SL_AT_G1 | AJ31: 0.29026695 | AK31: 1 | AL31: 0 | AM31: 35 | AN31: 0 | AO31: 0.00077925926 | AP31: 0 | AQ31: 0 | AR31: 0 | AS31: 0 | AT31: 0 | AU31: 0 | AV31: 0 | AW31: 0
A32: SL_AT_B4 | B32: SL_AT_B4/5 | C32: 2021/09/10 | D32: 紙谷 | E32: ヘルムホルツコイル | H32: TOKIN | AH32: SL_AT_G1 | AJ32: 0.29026695 | AK32: 1 | AL32: 0 | AM32: 35 | AN32: 0 | AO32: 0.00077925926 | AP32: 0 | AQ32: 0 | AR32: 0 | AS32: 0 | AT32: 0 | AU32: 0 | AV32: 0 | AW32: 0
A33: SL_AT_B5 | B33: SL_AT_B4/5 | C33: 2021/09/10 | D33: 紙谷 | E33: ヘルムホルツコイル | H33: TOKIN | AH33: SL_AT_G1 | AJ33: 0.29026695 | AK33: 1 | AL33: 0 | AM33: 35 | AN33: 0 | AO33: 0.00077925926 | AP33: 0 | AQ33: 0 | AR33: 0 | AS33: 0 | AT33: 0 | AU33: 0 | AV33: 0 | AW33: 0
A34: SX_AT_B4 | B34: SX_AT_B4 | C34: 2021/09/10 | D34: 横山/紙谷 | E34: ステアリング電磁石 | F34: main-linac | H34: Tokin | L34: 120 | M34: 800 | N34: 5 | P34: 7.415 | Q34: 90 | R34: 2.1 | T34: ? | U34: 1.483 | V34: 0.00215 | W34: air | AH34: SX_AT_B4 | AJ34: 0.74619 | AK34: 1 | AL34: -5 | AM34: 5 | AN34: 0 | AO34: 0.00032086 | AP34: 0 | AQ34: 0 | AR34: 0 | AS34: 0 | AT34: 0 | AU34: 0 | AV34: 0 | AW34: 0
A35: SY_AT_B4 | B35: SY_AT_B4 | C35: 2021/09/10 | D35: 横山/紙谷 | E35: ステアリング電磁石 | F35: main-linac | H35: Tokin | L35: 120 | M35: 800 | N35: 5 | P35: 7.415 | Q35: 90 | R35: 2.1 | T35: ? | U35: 1.483 | V35: 0.00215 | W35: air | AH35: SX_AT_B4 | AJ35: 0.74619 | AK35: 1 | AL35: -5 | AM35: 5 | AN35: 0 | AO35: 0.00032086 | AP35: 0 | AQ35: 0 | AR35: 0 | AS35: 0 | AT35: 0 | AU35: 0 | AV35: 0 | AW35: 0
A36: SL_AT_B6 | B36: SL_AT_B6/7 | C36: 2021/09/10 | D36: 紙谷 | E36: ヘルムホルツコイル | H36: TOKIN | AH36: SL_AT_G1 | AJ36: 0.29026695 | AK36: 1 | AL36: 0 | AM36: 35 | AN36: 0 | AO36: 0.00077925926 | AP36: 0 | AQ36: 0 | AR36: 0 | AS36: 0 | AT36: 0 | AU36: 0 | AV36: 0 | AW36: 0
A37: SL_AT_B7 | B37: SL_AT_B6/7 | C37: 2021/09/10 | D37: 紙谷 | E37: ヘルムホルツコイル | H37: TOKIN | AH37: SL_AT_G1 | AJ37: 0.29026695 | AK37: 1 | AL37: 0 | AM37: 35 | AN37: 0 | AO37: 0.00077925926 | AP37: 0 | AQ37: 0 | AR37: 0 | AS37: 0 | AT37: 0 | AU37: 0 | AV37: 0 | AW37: 0
A38: SL_AT_B8 | B38: SL_AT_B8 | C38: 2021/09/10 | D38: 紙谷 | E38: ヘルムホルツコイル | H38: TOKIN | AH38: SL_AT_G1 | AJ38: 0.29026695 | AK38: 1 | AL38: 0 | AM38: 35 | AN38: 0 | AO38: 0.00077925926 | AP38: 0 | AQ38: 0 | AR38: 0 | AS38: 0 | AT38: 0 | AU38: 0 | AV38: 0 | AW38: 0
A39: QD_AT_01 | B39: QD_AT_01 | C39: 2021/09/10 | D39: 横山/紙谷 | E39: 四極電磁石 | F39: main-linac | H39: Toyama | L39: 44 | M39: 50 | N39: 5 | P39: 4.75 | Q39: 296 | R39: 2 | T39: ? | U39: 0.95 | V39: 7.6852184 | W39: air | AH39: QD_AT_01 | AJ39: 0.0725 | AK39: 1 | AL39: 0 | AM39: 5 | AN39: 0.0052238785 | AO39: 0.1147566 | AP39: -1.6062238e-05 | AQ39: -1.1173023e-05 | AR39: -3.1943789e-05 | AS39: -4.5542558e-06 | AT39: 2.4099708e-06 | AU39: -2.6379341e-07 | AV39: 0 | AW39: 0
A40: QF_AT_02 | B40: QF_AT_02 | C40: 2021/09/10 | D40: 横山/紙谷 | E40: 四極電磁石 | F40: main-linac | H40: Toyama | L40: 44 | M40: 100 | N40: 5 | P40: 6 | Q40: 296 | R40: 2 | T40: ? | U40: 1.2 | V40: 7.6852184 | W40: air | AH40: QF_AT_02 | AJ40: 0.122 | AK40: 1 | AL40: 0 | AM40: 5 | AN40: 0.0023310868 | AO40: 0.16915601 | AP40: 0.046081187 | AQ40: -0.03915518 | AR40: 0.01749921 | AS40: -0.0042939396 | AT40: 0.00054370346 | AU40: -2.784529e-05 | AV40: 0 | AW40: 0
...

Sheet 設計座標
A1: regend : | J1: z : 175 (qd_a1_11 の BL からリフレクタ台座) + 25 (HUBBS ネスト + 1.5" リフレクタ) = 200 --> -70
B2: a : acceleration tubes | C2: d : designed or calculated | D2: a : active flag | J2: z0 の基準 : A1/AS のビームレベルを 0 mm, 値はリフレクタ中心．
B3: f : fiducial points | C3: s : surveyed | J3: ac_* の水準 (z0) はビームレベル．
B4: m : magnets | J4: Length : 電磁石・ソレノイドの場合は磁極長，ビームストッパ・コリメータの場合はビーム進行方向長さ．
B5: d : diagnostics
B6: v : vacuum components
B7: g : gun
B8: s : solenoid
B9: sa : solenoid on acceleration tube
B10: ss : solenoid in solenoid
A12: Beam source | B12: inst_type | C12: d/s | E12: Point name | F12: Element name | G12: s [m] | H12: x [mm] | I12: y [mm] | J12: z [mm] | K12: z0 [mm] | L12: Length [mm] | M12: Bore dia/DA [mm] | O12: 備考
A13: AS | B13: g | C13: d | D13: a | E13: gr_as | F13: gr_as | G13: =$G$14-564.0184/1000 -> -4.3755336 | H13: =$H$14-564.0184 -> -3513.6945 | I13: -9209.3249 | J13: -270 | K13: 0 | L13: 0
A14: AS | B14: s | C14: d | D14: a | E14: sx_as_1c | F14: sx_as_1 | G14: -3.8115152 | H14: -2949.6761 | I14: -9209.3249 | J14: -160 | K14: 110 | L14: 68 | M14: =_xlfn.XLOOKUP(F14,magnet_list!$A$2:$A$592,magnet_list!$L$2:$L$592,"n/a",0,1) -> 80 | O14: edge nest survey
A15: AS | B15: s | C15: d | D15: a | E15: sy_as_1c | F15: sy_as_1 | G15: -3.8115152 | H15: -2949.6761 | I15: -9209.3249 | J15: -160 | K15: 110 | L15: 68 | M15: =_xlfn.XLOOKUP(F15,magnet_list!$A$2:$A$592,magnet_list!$L$2:$L$592,"n/a",0,1) -> 80 | O15: edge nest survey
A16: AS | B16: d | C16: d | D16: a | E16: sc_as_0 | F16: sc_as_0 | G16: =G17-106.5/1000 -> -3.4624152 | H16: -2600.5761 | I16: -9209.3249 | J16: -270 | K16: 0
A17: AS | B17: d | C17: d | D17: a | E17: sp_as_1 | F17: sp_as_1 | G17: =G18-56/1000 -> -3.3559152 | H17: -2494.0761 | I17: -9209.3249 | J17: -270 | K17: 0
A18: AS | B18: m | C18: d | D18: a | E18: qf_as_1c | F18: qf_as_1 | G18: -3.2999152 | H18: -2438.0761 | I18: -9209.3249 | J18: -125 | K18: 145 | L18: 50 | M18: =_xlfn.XLOOKUP(F18,magnet_list!$A$2:$A$592,magnet_list!$L$2:$L$592,"n/a",0,1) -> 44 | O18: edge nest survey
A19: AS | B19: m | C19: d | D19: a | E19: qd_as_1c | F19: qd_as_1 | G19: -3.1499152 | H19: -2288.0761 | I19: -9209.3249 | J19: -125 | K19: 145 | L19: 50 | M19: =_xlfn.XLOOKUP(F19,magnet_list!$A$2:$A$592,magnet_list!$L$2:$L$592,"n/a",0,1) -> 44 | O19: edge nest survey
A20: AS | B20: s | C20: d | D20: a | E20: sx_as_2c | F20: sx_as_2 | G20: -2.9909152 | H20: -2129.0761 | I20: -9209.3249 | J20: -160 | K20: 110 | L20: 68 | M20: =_xlfn.XLOOKUP(F20,magnet_list!$A$2:$A$592,magnet_list!$L$2:$L$592,"n/a",0,1) -> 80 | O20: edge nest survey
A21: AS | B21: s | C21: d | D21: a | E21: sy_as_2c | F21: sy_as_2 | G21: -2.9909152 | H21: -2129.0761 | I21: -9209.3249 | J21: -160 | K21: 110 | L21: 68 | M21: =_xlfn.XLOOKUP(F21,magnet_list!$A$2:$A$592,magnet_list!$L$2:$L$592,"n/a",0,1) -> 80 | O21: edge nest survey
A22: AS | B22: m | C22: d | D22: a | E22: bm_as_1c | F22: bm_as_1 | G22: -2.5606722 | H22: -1703.8409 | I22: -9171.2647 | J22: -125 | K22: 145 | L22: 392.7005 | M22: =_xlfn.XLOOKUP(F22,magnet_list!$A$2:$A$592,magnet_list!$L$2:$L$592,"n/a",0,1) -> 30 | O22: edge nest survey
A23: AT | B23: d | C23: d | D23: a | E23: sp_at_0 | F23: sp_at_0 | G23: =$G$112-ABS($I$112-I23)/1000 -> -2.6197772 | H23: 0 | I23: -9862.4183 | J23: 480 | K23: 750
A24: AT | B24: m | C24: d | D24: a | E24: qd_at_01c | F24: qd_at_01 | G24: =$G$112-ABS($I$112-I24)/1000 -> -2.5382772 | H24: 0 | I24: -9780.9183 | J24: 642 | K24: 912 | L24: 50 | M24: =_xlfn.XLOOKUP(F24,magnet_list!$A$2:$A$592,magnet_list!$L$2:$L$592,"n/a",0,1) -> 44
A25: AT | B25: m | C25: s | E25: qf_at_02 | F25: qf_at_02 | G25: =$G$112-ABS($I$112-I25)/1000 -> -2.3932772 | H25: 0 | I25: -9635.9183 | J25: 642 | K25: 912 | L25: 100 | M25: =_xlfn.XLOOKUP(F25,magnet_list!$A$2:$A$592,magnet_list!$L$2:$L$592,"n/a",0,1) -> 44
A26: AT | B26: m | C26: d | D26: a | E26: qf_at_02c | F26: qf_at_02 | G26: =$G$112-ABS($I$112-I26)/1000 -> -2.3632771 | H26: 0 | I26: -9605.9182 | J26: 642 | K26: 912 | L26: 100 | M26: =_xlfn.XLOOKUP(F26,magnet_list!$A$2:$A$592,magnet_list!$L$2:$L$592,"n/a",0,1) -> 44
A27: AT | B27: m | C27: d | D27: a | E27: qd_at_03c | F27: qd_at_03 | G27: =$G$112-ABS($I$112-I27)/1000 -> -2.2084702 | H27: 0 | I27: -9451.1113 | J27: 642 | K27: 912 | L27: 50 | M27: =_xlfn.XLOOKUP(F27,magnet_list!$A$2:$A$592,magnet_list!$L$2:$L$592,"n/a",0,1) -> 44
A28: AT | B28: m | C28: s | E28: qd_at_03 | F28: qd_at_03 | G28: =$G$112-ABS($I$112-I28)/1000 -> -2.2034702 | H28: 0 | I28: -9446.1113 | J28: 642 | K28: 912 | L28: 50 | M28: =_xlfn.XLOOKUP(F28,magnet_list!$A$2:$A$592,magnet_list!$L$2:$L$592,"n/a",0,1) -> 44
A29: AT | B29: d | C29: d | D29: a | E29: sc_at_0 | F29: sc_at_0 | G29: =$G$112-ABS($I$112-I29)/1000 -> -2.0799702 | H29: 0 | I29: -9322.6113 | J29: 480 | K29: 750
A30: AS | B30: d | C30: d | D30: a | E30: sp_as_2 | F30: sp_as_2 | G30: =G31-56/1000 -> -2.1474295 | H30: -1388.2627 | I30: -8909.5117 | J30: -270 | K30: 0
A31: AS | B31: m | C31: d | D31: a | E31: qf_as_2c | F31: qf_as_2 | G31: -2.0914295 | H31: -1348.6647 | I31: -8860.5577 | J31: -125 | K31: 145 | L31: 50 | M31: =_xlfn.XLOOKUP(F31,magnet_list!$A$2:$A$592,magnet_list!$L$2:$L$592,"n/a",0,1) -> 44 | O31: edge nest survey
A32: AS | B32: m | C32: d | D32: a | E32: qd_as_2c | F32: qd_as_2 | G32: -1.9414295 | H32: -1242.5987 | I32: -8754.4916 | J32: -125 | K32: 145 | L32: 50 | M32: =_xlfn.XLOOKUP(F32,magnet_list!$A$2:$A$592,magnet_list!$L$2:$L$592,"n/a",0,1) -> 44 | O32: edge nest survey
A33: AT | B33: m | C33: d | D33: a | E33: bx_at_0c | F33: bx_at_0 | G33: =$G$112-ABS($I$112-I33)/1000 -> -1.9197039 | H33: 0 | I33: -9162.345 | J33: 575 | K33: 845 | L33: 50 | M33: =_xlfn.XLOOKUP(F33,magnet_list!$A$2:$A$592,magnet_list!$L$2:$L$592,"n/a",0,1) -> 82 | O33: edge nest survey
A34: AT | B34: m | C34: d | D34: a | E34: by_at_0c | F34: by_at_0 | G34: =$G$112-ABS($I$112-I34)/1000 -> -1.9197039 | H34: 0 | I34: -9162.345 | J34: 575 | K34: 845 | L34: 50 | M34: =_xlfn.XLOOKUP(F34,magnet_list!$A$2:$A$592,magnet_list!$L$2:$L$592,"n/a",0,1) -> 82 | O34: edge nest survey
A35: AT | B35: a | C35: d | D35: a | E35: ac_at_1u | F35: ac_at_1 | G35: =$G$112-ABS($I$112-I35)/1000 -> -1.7405885 | H35: 0 | I35: =$I$47-$L$47/2 -> -8983.2296 | J35: 480 | K35: 750 | L35: 1889.4492
A36: AT | B36: sa | C36: d | D36: a | E36: sx_at_1 | F36: sx_at_1 | G36: =$G$112-ABS($I$112-I36)/1000 -> -1.0571089 | H36: 0 | I36: -8299.75 | J36: 480 | K36: 750 | L36: 1000 | M36: =_xlfn.XLOOKUP(F36,magnet_list!$A$2:$A$592,magnet_list!$L$2:$L$592,"n/a",0,1) -> 120
A37: AT | B37: sa | C37: d | D37: a | E37: sy_at_1 | F37: sy_at_1 | G37: =$G$112-ABS($I$112-I37)/1000 -> -1.0571089 | H37: 0 | I37: -8299.75 | J37: 480 | K37: 750 | L37: 1000 | M37: =_xlfn.XLOOKUP(F37,magnet_list!$A$2:$A$592,magnet_list!$L$2:$L$592,"n/a",0,1) -> 120
A38: A1 | B38: g | C38: d | D38: a | E38: gr_a1 | F38: gr_a1 | G38: =$G$39-312.3/1000 -> -1.8603869 | H38: 0 | I38: =$I$39-312.3 -> -9189.1279 | J38: -270 | K38: 0
A39: A1 | B39: m | C39: d | D39: a | E39: solenoid_coil | F39: solenoid_coil | G39: =$G$40-305/1000 -> -1.5480869 | H39: 0 | I39: =$I$40-305 -> -8876.8279 | J39: -270 | K39: 0 | L39: 40
A40: A1 | B40: v | C40: d | D40: a | E40: gv_a1_rg | F40: gv_a1_rg | G40: =$G$41-301/1000 -> -1.2430869 | H40: 0 | I40: =$I$42-301 -> -8571.8279 | J40: -270 | K40: 0
A41: A1 | B41: d | C41: d | D41: a | E41: sp_a1_g | F41: sp_a1_g | G41: =$G$42-72/1000 -> -0.9420869 | H41: 0 | I41: =$I$42-72 -> -8342.8279 | J41: -270 | K41: 0
...

Sheet 測地線補正
D1: 20160929 | E1: 20180925 | N1: c0 | O1: c1 | P1: c2 | Q1: c3 | R1: c4
A2: Point Name | B2: s [m] | C2: y [m] | D2: z [mm] | E2: z [mm] | F2: z [mm] | G2: z' [mm] | H2: z" [mm] | I2: Δz [mm] | L2: =SUM(L26:L105) -> -0.38854381 | M2: 3rd | N2: -1.4231 | O2: -0.046848 | P2: -0.00015869 | Q2: -1.3568e-07 | U2: =SUM(K26:K105) -> 4.035511
A3: pd_a1d | B3: 8.08278 | C3: =_xlfn.XLOOKUP($A3,[1]usmn_pd!$A$2:$A$118,[1]usmn_pd!$D$2:$D$118,"n/a",0,1)/1000 -> 0.69341315 | E3: 0.13295088 | F3: =_xlfn.XLOOKUP($A3,[1]usmn_pd!$A$2:$A$118,[1]usmn_pd!$F$2:$F$118,"n/a",0,1) -> 0 | G3: =F3-($F$3-$F$24)/($C$3-$C$24)*($C3-$C$24)-$F$24 -> 0 | H3: =G3+($E$3-$E$24)/($C$3-$C$24)*($C3-$C$24)+$E$24 -> 0.13295088 | I3: =$E3-_xlfn.XLOOKUP($A3,[1]usmn_pd!$A$2:$A$118,[1]usmn_pd!$F$2:$F$118,"n/a",0,1) -> 0.13295088 | M3: 3rd | N3: 0.027195 | O3: -0.092467 | P3: 0.00057087 | Q3: -4.1453e-06
A4: pd_a2u | B4: 8.452527 | C4: =_xlfn.XLOOKUP($A4,[1]usmn_pd!$A$2:$A$118,[1]usmn_pd!$D$2:$D$118,"n/a",0,1)/1000 -> 1.0631862 | E4: 0.15382667 | F4: =_xlfn.XLOOKUP($A4,[1]usmn_pd!$A$2:$A$118,[1]usmn_pd!$F$2:$F$118,"n/a",0,1) -> 0.32884537 | G4: =F4-($F$3-$F$24)/($C$3-$C$24)*($C4-$C$24)-$F$24 -> 0.29921144 | H4: =G4+($E$3-$E$24)/($C$3-$C$24)*($C4-$C$24)+$E$24 -> 0.43144727 | I4: =$E4-_xlfn.XLOOKUP($A4,[1]usmn_pd!$A$2:$A$118,[1]usmn_pd!$F$2:$F$118,"n/a",0,1) -> -0.1750187
A5: pd_a2d | B5: 19.099688 | C5: =_xlfn.XLOOKUP($A5,[1]usmn_pd!$A$2:$A$118,[1]usmn_pd!$D$2:$D$118,"n/a",0,1)/1000 -> 11.710309 | E5: 0.13760008 | F5: =_xlfn.XLOOKUP($A5,[1]usmn_pd!$A$2:$A$118,[1]usmn_pd!$F$2:$F$118,"n/a",0,1) -> 1.1982532 | G5: =F5-($F$3-$F$24)/($C$3-$C$24)*($C5-$C$24)-$F$24 -> 0.31534957 | H5: =G5+($E$3-$E$24)/($C$3-$C$24)*($C5-$C$24)+$E$24 -> 0.42699658 | I5: =$E5-_xlfn.XLOOKUP($A5,[1]usmn_pd!$A$2:$A$118,[1]usmn_pd!$F$2:$F$118,"n/a",0,1) -> -1.0606531
A6: pd_a3u | B6: 20.313375 | C6: =_xlfn.XLOOKUP($A6,[1]usmn_pd!$A$2:$A$118,[1]usmn_pd!$D$2:$D$118,"n/a",0,1)/1000 -> 12.924014 | E6: -0.075108751 | F6: =_xlfn.XLOOKUP($A6,[1]usmn_pd!$A$2:$A$118,[1]usmn_pd!$F$2:$F$118,"n/a",0,1) -> 0.97148748 | G6: =F6-($F$3-$F$24)/($C$3-$C$24)*($C6-$C$24)-$F$24 -> -0.0086835052 | H6: =G6+($E$3-$E$24)/($C$3-$C$24)*($C6-$C$24)+$E$24 -> 0.10061651 | I6: =$E6-_xlfn.XLOOKUP($A6,[1]usmn_pd!$A$2:$A$118,[1]usmn_pd!$F$2:$F$118,"n/a",0,1) -> -1.0465962
A7: pd_a3d | B7: 29.700553 | C7: =_xlfn.XLOOKUP($A7,[1]usmn_pd!$A$2:$A$118,[1]usmn_pd!$D$2:$D$118,"n/a",0,1)/1000 -> 22.311177 | E7: -0.33716254 | F7: =_xlfn.XLOOKUP($A7,[1]usmn_pd!$A$2:$A$118,[1]usmn_pd!$F$2:$F$118,"n/a",0,1) -> 1.7136212 | G7: =F7-($F$3-$F$24)/($C$3-$C$24)*($C7-$C$24)-$F$24 -> -0.018845173 | H7: =G7+($E$3-$E$24)/($C$3-$C$24)*($C7-$C$24)+$E$24 -> 0.072302455 | I7: =$E7-_xlfn.XLOOKUP($A7,[1]usmn_pd!$A$2:$A$118,[1]usmn_pd!$F$2:$F$118,"n/a",0,1) -> -2.0507837
A8: pd_a4u | B8: 30.814762 | C8: =_xlfn.XLOOKUP($A8,[1]usmn_pd!$A$2:$A$118,[1]usmn_pd!$D$2:$D$118,"n/a",0,1)/1000 -> 23.425386 | E8: -0.18536829 | F8: =_xlfn.XLOOKUP($A8,[1]usmn_pd!$A$2:$A$118,[1]usmn_pd!$F$2:$F$118,"n/a",0,1) -> 1.7725789 | G8: =F8-($F$3-$F$24)/($C$3-$C$24)*($C8-$C$24)-$F$24 -> -0.049181162 | H8: =G8+($E$3-$E$24)/($C$3-$C$24)*($C8-$C$24)+$E$24 -> 0.039811868 | I8: =$E8-_xlfn.XLOOKUP($A8,[1]usmn_pd!$A$2:$A$118,[1]usmn_pd!$F$2:$F$118,"n/a",0,1) -> -1.9579472
A9: pd_a4d | B9: 40.202587 | C9: =_xlfn.XLOOKUP($A9,[1]usmn_pd!$A$2:$A$118,[1]usmn_pd!$D$2:$D$118,"n/a",0,1)/1000 -> 32.813161 | E9: -0.1277241 | F9: =_xlfn.XLOOKUP($A9,[1]usmn_pd!$A$2:$A$118,[1]usmn_pd!$F$2:$F$118,"n/a",0,1) -> 2.2868187 | G9: =F9-($F$3-$F$24)/($C$3-$C$24)*($C9-$C$24)-$F$24 -> -0.28728583 | H9: =G9+($E$3-$E$24)/($C$3-$C$24)*($C9-$C$24)+$E$24 -> -0.21644637 | I9: =$E9-_xlfn.XLOOKUP($A9,[1]usmn_pd!$A$2:$A$118,[1]usmn_pd!$F$2:$F$118,"n/a",0,1) -> -2.4145428
A10: pd_b1u | B10: 43.953697 | C10: =_xlfn.XLOOKUP($A10,[1]usmn_pd!$A$2:$A$118,[1]usmn_pd!$D$2:$D$118,"n/a",0,1)/1000 -> 36.56427 | E10: -0.093785814 | F10: =_xlfn.XLOOKUP($A10,[1]usmn_pd!$A$2:$A$118,[1]usmn_pd!$F$2:$F$118,"n/a",0,1) -> 2.4052239 | G10: =F10-($F$3-$F$24)/($C$3-$C$24)*($C10-$C$24)-$F$24 -> -0.46949778 | H10: =G10+($E$3-$E$24)/($C$3-$C$24)*($C10-$C$24)+$E$24 -> -0.40591201 | I10: =$E10-_xlfn.XLOOKUP($A10,[1]usmn_pd!$A$2:$A$118,[1]usmn_pd!$F$2:$F$118,"n/a",0,1) -> -2.4990097
A11: pd_b2u | B11: 53.461811 | C11: =_xlfn.XLOOKUP($A11,[1]usmn_pd!$A$2:$A$118,[1]usmn_pd!$D$2:$D$118,"n/a",0,1)/1000 -> 46.072349 | E11: -0.070593314 | F11: =_xlfn.XLOOKUP($A11,[1]usmn_pd!$A$2:$A$118,[1]usmn_pd!$F$2:$F$118,"n/a",0,1) -> 3.165681 | G11: =F11-($F$3-$F$24)/($C$3-$C$24)*($C11-$C$24)-$F$24 -> -0.47102643 | H11: =G11+($E$3-$E$24)/($C$3-$C$24)*($C11-$C$24)+$E$24 -> -0.42582687 | I11: =$E11-_xlfn.XLOOKUP($A11,[1]usmn_pd!$A$2:$A$118,[1]usmn_pd!$F$2:$F$118,"n/a",0,1) -> -3.2362743
A12: pd_b2d | B12: 62.010359 | C12: =_xlfn.XLOOKUP($A12,[1]usmn_pd!$A$2:$A$118,[1]usmn_pd!$D$2:$D$118,"n/a",0,1)/1000 -> 54.62086 | E12: -0.10241059 | F12: =_xlfn.XLOOKUP($A12,[1]usmn_pd!$A$2:$A$118,[1]usmn_pd!$F$2:$F$118,"n/a",0,1) -> 3.9648493 | G12: =F12-($F$3-$F$24)/($C$3-$C$24)*($C12-$C$24)-$F$24 -> -0.35694323 | H12: =G12+($E$3-$E$24)/($C$3-$C$24)*($C12-$C$24)+$E$24 -> -0.32827431 | I12: =$E12-_xlfn.XLOOKUP($A12,[1]usmn_pd!$A$2:$A$118,[1]usmn_pd!$F$2:$F$118,"n/a",0,1) -> -4.0672599
A13: pd_b3u | B13: 63.150419 | C13: =_xlfn.XLOOKUP($A13,[1]usmn_pd!$A$2:$A$118,[1]usmn_pd!$D$2:$D$118,"n/a",0,1)/1000 -> 55.760873 | E13: -0.063009917 | F13: =_xlfn.XLOOKUP($A13,[1]usmn_pd!$A$2:$A$118,[1]usmn_pd!$F$2:$F$118,"n/a",0,1) -> 3.9566328 | G13: =F13-($F$3-$F$24)/($C$3-$C$24)*($C13-$C$24)-$F$24 -> -0.45652133 | H13: =G13+($E$3-$E$24)/($C$3-$C$24)*($C13-$C$24)+$E$24 -> -0.43005691 | I13: =$E13-_xlfn.XLOOKUP($A13,[1]usmn_pd!$A$2:$A$118,[1]usmn_pd!$F$2:$F$118,"n/a",0,1) -> -4.0196427
A14: pd_b3d | B14: 71.698403 | C14: =_xlfn.XLOOKUP($A14,[1]usmn_pd!$A$2:$A$118,[1]usmn_pd!$D$2:$D$118,"n/a",0,1)/1000 -> 64.308843 | E14: 0.025925552 | F14: =_xlfn.XLOOKUP($A14,[1]usmn_pd!$A$2:$A$118,[1]usmn_pd!$F$2:$F$118,"n/a",0,1) -> 4.9925492 | G14: =F14-($F$3-$F$24)/($C$3-$C$24)*($C14-$C$24)-$F$24 -> -0.10564664 | H14: =G14+($E$3-$E$24)/($C$3-$C$24)*($C14-$C$24)+$E$24 -> -0.095711819 | I14: =$E14-_xlfn.XLOOKUP($A14,[1]usmn_pd!$A$2:$A$118,[1]usmn_pd!$F$2:$F$118,"n/a",0,1) -> -4.9666236
A15: pd_b4u | B15: 72.750066 | C15: =_xlfn.XLOOKUP($A15,[1]usmn_pd!$A$2:$A$118,[1]usmn_pd!$D$2:$D$118,"n/a",0,1)/1000 -> 65.36049 | E15: 0.25589642 | F15: =_xlfn.XLOOKUP($A15,[1]usmn_pd!$A$2:$A$118,[1]usmn_pd!$F$2:$F$118,"n/a",0,1) -> 5.0987181 | G15: =F15-($F$3-$F$24)/($C$3-$C$24)*($C15-$C$24)-$F$24 -> -0.083757662 | H15: =G15+($E$3-$E$24)/($C$3-$C$24)*($C15-$C$24)+$E$24 -> -0.075856459 | I15: =$E15-_xlfn.XLOOKUP($A15,[1]usmn_pd!$A$2:$A$118,[1]usmn_pd!$F$2:$F$118,"n/a",0,1) -> -4.8428217
... A24: pd_b8d | B24: 119.6951 | C24: =_xlfn.XLOOKUP($A24,[1]usmn_pd!$A$2:$A$118,[1]usmn_pd!$D$2:$D$118,"n/a",0,1)/1000 -> 112.30557 | E24: -0.08287865 | F24: =_xlfn.XLOOKUP($A24,[1]usmn_pd!$A$2:$A$118,[1]usmn_pd!$F$2:$F$118,"n/a",0,1) -> 8.9446956 | G24: =F24-($F$3-$F$24)/($C$3-$C$24)*($C24-$C$24)-$F$24 -> 0 | H24: =G24+($E$3-$E$24)/($C$3-$C$24)*($C24-$C$24)+$E$24 -> -0.08287865 | I24: =$E24-_xlfn.XLOOKUP($A24,[1]usmn_pd!$A$2:$A$118,[1]usmn_pd!$F$2:$F$118,"n/a",0,1) -> -9.0275742
A26: pd_r063u | B26: =VLOOKUP(A26,[2]usmn_ana14_pd!$A$2:$B$119,2,FALSE) -> 152.47843 | C26: =_xlfn.XLOOKUP($A26,[1]usmn_pd!$A$2:$A$118,[1]usmn_pd!$D$2:$D$118,"n/a",0,1)/1000 -> 111.88289 | D26: -0.027450181 | F26: =_xlfn.XLOOKUP($A26,[1]usmn_pd!$A$2:$A$118,[1]usmn_pd!$F$2:$F$118,"N/A",0,1) -> 8.5861619 | G26: =F26-($F$26-$F$105)/($C$26*1000-$C$105*1000)*($C26*1000-$C$105*1000)-$F$105 -> 0 | H26: =G26+($D$26-$D$105)/($C$26*1000-$C$105*1000)*($C26*1000-$C$105*1000)+$D$105 -> -0.027450181 | I26: =$D26-VLOOKUP($A26,[1]usmn_pd!$A$2:$F$118,6,FALSE) -> -8.6136121 | J26: =$Q$2*$C26^3+$P$2*$C26^2+$O$2*$C26+$N$2 -> -8.8410595 | K26: =(I26-J26)^2 -> 0.051732312 | L26: =K26/J26 -> -0.0058513702 | M26: 3rd | N26: -1.4231 | O26: -0.046848 | P26: -0.00015869 | Q26: -1.3568e-07
A27: pd_r063d | B27: =VLOOKUP(A27,[2]usmn_ana14_pd!$A$2:$B$119,2,FALSE) -> 153.98864 | C27: =_xlfn.XLOOKUP($A27,[1]usmn_pd!$A$2:$A$118,[1]usmn_pd!$D$2:$D$118,"n/a",0,1)/1000 -> 110.37268 | D27: -0.1325276 | F27: =_xlfn.XLOOKUP($A27,[1]usmn_pd!$A$2:$A$118,[1]usmn_pd!$F$2:$F$118,"N/A",0,1) -> 8.4759196 | G27: =F27-($F$26-$F$105)/($C$26*1000-$C$105*1000)*($C27*1000-$C$105*1000)-$F$105 -> -0.079250114 | H27: =G27+($D$26-$D$105)/($C$26*1000-$C$105*1000)*($C27*1000-$C$105*1000)+$D$105 -> -0.10620734 | I27: =$D27-VLOOKUP($A27,[1]usmn_pd!$A$2:$F$118,6,FALSE) -> -8.6084472 | J27: =$Q$2*$C27^3+$P$2*$C27^2+$O$2*$C27+$N$2 -> -8.7094531 | K27: =(I27-J27)^2 -> 0.010202193 | L27: =K27/J27 -> -0.001171393
A28: pd_c1u | B28: =VLOOKUP(A28,[2]usmn_ana14_pd!$A$2:$B$119,2,FALSE) -> 156.54551 | C28: =_xlfn.XLOOKUP($A28,[1]usmn_pd!$A$2:$A$118,[1]usmn_pd!$D$2:$D$118,"n/a",0,1)/1000 -> 107.81579 | D28: -0.30836283 | F28: =_xlfn.XLOOKUP($A28,[1]usmn_pd!$A$2:$A$118,[1]usmn_pd!$F$2:$F$118,"N/A",0,1) -> 7.9798248 | G28: =F28-($F$26-$F$105)/($C$26*1000-$C$105*1000)*($C28*1000-$C$105*1000)-$F$105 -> -0.522873 | H28: =G28+($D$26-$D$105)/($C$26*1000-$C$105*1000)*($C28*1000-$C$105*1000)+$D$105 -> -0.54899562 | I28: =$D28-VLOOKUP($A28,[1]usmn_pd!$A$2:$F$118,6,FALSE) -> -8.2881876 | J28: =$Q$2*$C28^3+$P$2*$C28^2+$O$2*$C28+$N$2 -> -8.4887504 | K28: =(I28-J28)^2 -> 0.040225427 | L28: =K28/J28 -> -0.0047386747 | N28: PD 傾き [rad] | P28: =ATAN(($D$26-$D$105)/($C$26*1000-$C$105*1000)) -> -3.2641553e-07
A29: pd_c1d | B29: =VLOOKUP(A29,[2]usmn_ana14_pd!$A$2:$B$119,2,FALSE) -> 165.26052 | C29: =_xlfn.XLOOKUP($A29,[1]usmn_pd!$A$2:$A$118,[1]usmn_pd!$D$2:$D$118,"n/a",0,1)/1000 -> 99.100726 | D29: -0.29240465 | F29: =_xlfn.XLOOKUP($A29,[1]usmn_pd!$A$2:$A$118,[1]usmn_pd!$F$2:$F$118,"N/A",0,1) -> 7.1568697 | G29: =F29-($F$26-$F$105)/($C$26*1000-$C$105*1000)*($C29*1000-$C$105*1000)-$F$105 -> -1.1669793 | H29: =G29+($D$26-$D$105)/($C$26*1000-$C$105*1000)*($C29*1000-$C$105*1000)+$D$105 -> -1.1902572 | I29: =$D29-VLOOKUP($A29,[1]usmn_pd!$A$2:$F$118,6,FALSE) -> -7.4492743 | J29: =$Q$2*$C29^3+$P$2*$C29^2+$O$2*$C29+$N$2 -> -7.7563104 | K29: =(I29-J29)^2 -> 0.09427116 | L29: =K29/J29 -> -0.012154124 | N29: LT 傾き [rad] | P29: =ATAN(($F$26-$F$105)/($C$26*1000-$C$105*1000)) -> 2.0521794e-05
A30: pd_c2u | B30: =VLOOKUP(A30,[2]usmn_ana14_pd!$A$2:$B$119,2,FALSE) -> 166.14232 | C30: =_xlfn.XLOOKUP($A30,[1]usmn_pd!$A$2:$A$118,[1]usmn_pd!$D$2:$D$118,"n/a",0,1)/1000 -> 98.21896 | D30: -0.33990307 | F30: =_xlfn.XLOOKUP($A30,[1]usmn_pd!$A$2:$A$118,[1]usmn_pd!$F$2:$F$118,"N/A",0,1) -> 7.7999047 | G30: =F30-($F$26-$F$105)/($C$26*1000-$C$105*1000)*($C30*1000-$C$105*1000)-$F$105 -> -0.50584884 | H30: =G30+($D$26-$D$105)/($C$26*1000-$C$105*1000)*($C30*1000-$C$105*1000)+$D$105 -> -0.52883891 | I30: =$D30-VLOOKUP($A30,[1]usmn_pd!$A$2:$F$118,6,FALSE) -> -8.1398078 | J30: =$Q$2*$C30^3+$P$2*$C30^2+$O$2*$C30+$N$2 -> -7.6838974 | K30: =(I30-J30)^2 -> 0.2078543 | L30: =K30/J30 -> -0.027050635
A31: pd_c2d | B31: =VLOOKUP(A31,[2]usmn_ana14_pd!$A$2:$B$119,2,FALSE) -> 174.85891 | C31: =_xlfn.XLOOKUP($A31,[1]usmn_pd!$A$2:$A$118,[1]usmn_pd!$D$2:$D$118,"n/a",0,1)/1000 -> 89.502262 | D31: -0.33030504 | F31: =_xlfn.XLOOKUP($A31,[1]usmn_pd!$A$2:$A$118,[1]usmn_pd!$F$2:$F$118,"N/A",0,1) -> 6.7852867 | G31: =F31-($F$26-$F$105)/($C$26*1000-$C$105*1000)*($C31*1000-$C$105*1000)-$F$105 -> -1.3415846 | H31: =G31+($D$26-$D$105)/($C$26*1000-$C$105*1000)*($C31*1000-$C$105*1000)+$D$105 -> -1.3617294 | I31: =$D31-VLOOKUP($A31,[1]usmn_pd!$A$2:$F$118,6,FALSE) -> -7.1155917 | J31: =$Q$2*$C31^3+$P$2*$C31^2+$O$2*$C31+$N$2 -> -6.9845915 | K31: =(I31-J31)^2 -> 0.017161052 | L31: =K31/J31 -> -0.0024569872
A32: pd_c3u | B32: =VLOOKUP(A32,[2]usmn_ana14_pd!$A$2:$B$119,2,FALSE) -> 175.74262 | C32: =_xlfn.XLOOKUP($A32,[1]usmn_pd!$A$2:$A$118,[1]usmn_pd!$D$2:$D$118,"n/a",0,1)/1000 -> 88.618732 | D32: -0.57464007 | F32: =_xlfn.XLOOKUP($A32,[1]usmn_pd!$A$2:$A$118,[1]usmn_pd!$F$2:$F$118,"N/A",0,1) -> 6.6921719 | G32: =F32-($F$26-$F$105)/($C$26*1000-$C$105*1000)*($C32*1000-$C$105*1000)-$F$105 -> -1.4165678 | H32: =G32+($D$26-$D$105)/($C$26*1000-$C$105*1000)*($C32*1000-$C$105*1000)+$D$105 -> -1.4364242 | I32: =$D32-VLOOKUP($A32,[1]usmn_pd!$A$2:$F$118,6,FALSE) -> -7.2668119 | J32: =$Q$2*$C32^3+$P$2*$C32^2+$O$2*$C32+$N$2 -> -6.9153735 | K32: =(I32-J32)^2 -> 0.12350899 | L32: =K32/J32 -> -0.01786006
A33: pd_c4u | B33: =VLOOKUP(A33,[2]usmn_ana14_pd!$A$2:$B$119,2,FALSE) -> 185.33916 | C33: =_xlfn.XLOOKUP($A33,[1]usmn_pd!$A$2:$A$118,[1]usmn_pd!$D$2:$D$118,"n/a",0,1)/1000 -> 79.022111 | D33: -0.42151247 | F33: =_xlfn.XLOOKUP($A33,[1]usmn_pd!$A$2:$A$118,[1]usmn_pd!$F$2:$F$118,"N/A",0,1) -> 5.6420026 | G33: =F33-($F$26-$F$105)/($C$26*1000-$C$105*1000)*($C33*1000-$C$105*1000)-$F$105 -> -2.2697972 | H33: =G33+($D$26-$D$105)/($C$26*1000-$C$105*1000)*($C33*1000-$C$105*1000)+$D$105 -> -2.2865211 | I33: =$D33-VLOOKUP($A33,[1]usmn_pd!$A$2:$F$118,6,FALSE) -> -6.063515 | J33: =$Q$2*$C33^3+$P$2*$C33^2+$O$2*$C33+$N$2 -> -6.1830183 | K33: =(I33-J33)^2 -> 0.014281036 | L33: =K33/J33 -> -0.0023097192
A34: pd_c4d | B34: =VLOOKUP(A34,[2]usmn_ana14_pd!$A$2:$B$119,2,FALSE) -> 194.05496 | C34: =_xlfn.XLOOKUP($A34,[1]usmn_pd!$A$2:$A$118,[1]usmn_pd!$D$2:$D$118,"n/a",0,1)/1000 -> 70.306214 | D34: -0.55073983 | F34: =_xlfn.XLOOKUP($A34,[1]usmn_pd!$A$2:$A$118,[1]usmn_pd!$F$2:$F$118,"N/A",0,1) -> 4.9493897 | G34: =F34-($F$26-$F$105)/($C$26*1000-$C$105*1000)*($C34*1000-$C$105*1000)-$F$105 -> -2.7835443 | H34: =G34+($D$26-$D$105)/($C$26*1000-$C$105*1000)*($C34*1000-$C$105*1000)+$D$105 -> -2.7974232 | I34: =$D34-VLOOKUP($A34,[1]usmn_pd!$A$2:$F$118,6,FALSE) -> -5.5001295 | J34: =$Q$2*$C34^3+$P$2*$C34^2+$O$2*$C34+$N$2 -> -5.5483561 | K34: =(I34-J34)^2 -> 0.0023258019 | L34: =K34/J34 -> -0.00041918757
A35: pd_c5u | B35: =VLOOKUP(A35,[2]usmn_ana14_pd!$A$2:$B$119,2,FALSE) -> 194.94342 | C35: =_xlfn.XLOOKUP($A35,[1]usmn_pd!$A$2:$A$118,[1]usmn_pd!$D$2:$D$118,"n/a",0,1)/1000 -> 69.417902 | D35: -0.61277711 | F35: =_xlfn.XLOOKUP($A35,[1]usmn_pd!$A$2:$A$118,[1]usmn_pd!$F$2:$F$118,"N/A",0,1) -> 5.0002632 | G35: =F35-($F$26-$F$105)/($C$26*1000-$C$105*1000)*($C35*1000-$C$105*1000)-$F$105 -> -2.7144409 | H35: =G35+($D$26-$D$105)/($C$26*1000-$C$105*1000)*($C35*1000-$C$105*1000)+$D$105 -> -2.7280299 | I35: =$D35-VLOOKUP($A35,[1]usmn_pd!$A$2:$F$118,6,FALSE) -> -5.6130403 | J35: =$Q$2*$C35^3+$P$2*$C35^2+$O$2*$C35+$N$2 -> -5.4852793 | K35: =(I35-J35)^2 -> 0.016322887 | L35: =K35/J35 -> -0.0029757622
A36: pd_c5d | B36: =VLOOKUP(A36,[2]usmn_ana14_pd!$A$2:$B$119,2,FALSE) -> 203.65968 | C36: =_xlfn.XLOOKUP($A36,[1]usmn_pd!$A$2:$A$118,[1]usmn_pd!$D$2:$D$118,"n/a",0,1)/1000 -> 60.701588 | D36: -0.7320621 | F36: =_xlfn.XLOOKUP($A36,[1]usmn_pd!$A$2:$A$118,[1]usmn_pd!$F$2:$F$118,"N/A",0,1) -> 4.5463959 | G36: =F36-($F$26-$F$105)/($C$26*1000-$C$105*1000)*($C36*1000-$C$105*1000)-$F$105 -> -2.9894339 | H36: =G36+($D$26-$D$105)/($C$26*1000-$C$105*1000)*($C36*1000-$C$105*1000)+$D$105 -> -3.0001777 | I36: =$D36-VLOOKUP($A36,[1]usmn_pd!$A$2:$F$118,6,FALSE) -> -5.2784579 | J36: =$Q$2*$C36^3+$P$2*$C36^2+$O$2*$C36+$N$2 -> -4.8819173 | K36: =(I36-J36)^2 -> 0.15724445 | L36: =K36/J36 -> -0.032209569
A37: pd_c6u | B37: =VLOOKUP(A37,[2]usmn_ana14_pd!$A$2:$B$119,2,FALSE) -> 204.51867 | C37: =_xlfn.XLOOKUP($A37,[1]usmn_pd!$A$2:$A$118,[1]usmn_pd!$D$2:$D$118,"n/a",0,1)/1000 -> 59.842605 | D37: -0.73649151 | F37: =_xlfn.XLOOKUP($A37,[1]usmn_pd!$A$2:$A$118,[1]usmn_pd!$F$2:$F$118,"N/A",0,1) -> 4.4174911 | G37: =F37-($F$26-$F$105)/($C$26*1000-$C$105*1000)*($C37*1000-$C$105*1000)-$F$105 -> -3.1007108 | H37: =G37+($D$26-$D$105)/($C$26*1000-$C$105*1000)*($C37*1000-$C$105*1000)+$D$105 -> -3.1111742 | I37: =$D37-VLOOKUP($A37,[1]usmn_pd!$A$2:$F$118,6,FALSE) -> -5.1539826 | J37: =$Q$2*$C37^3+$P$2*$C37^2+$O$2*$C37+$N$2 -> -4.8239739 | K37: =(I37-J37)^2 -> 0.10890574 | L37: =K37/J37 -> -0.022575938
A38: pd_c6d | B38: =VLOOKUP(A38,[2]usmn_ana14_pd!$A$2:$B$119,2,FALSE) -> 213.2338 | C38: =_xlfn.XLOOKUP($A38,[1]usmn_pd!$A$2:$A$118,[1]usmn_pd!$D$2:$D$118,"n/a",0,1)/1000 -> 51.127445 | D38: -0.83140313 | F38: =_xlfn.XLOOKUP($A38,[1]usmn_pd!$A$2:$A$118,[1]usmn_pd!$F$2:$F$118,"N/A",0,1) -> 3.3177812 | G38: =F38-($F$26-$F$105)/($C$26*1000-$C$105*1000)*($C38*1000-$C$105*1000)-$F$105 -> -4.02157 | H38: =G38+($D$26-$D$105)/($C$26*1000-$C$105*1000)*($C38*1000-$C$105*1000)+$D$105 -> -4.0291886 | I38: =$D38-VLOOKUP($A38,[1]usmn_pd!$A$2:$F$118,6,FALSE) -> -4.1491843 | J38: =$Q$2*$C38^3+$P$2*$C38^2+$O$2*$C38+$N$2 -> -4.25127 | K38: =(I38-J38)^2 -> 0.010421489 | L38: =K38/J38 -> -0.0024513826
A39: pd_c7u | B39: =VLOOKUP(A39,[2]usmn_ana14_pd!$A$2:$B$119,2,FALSE) -> 214.19955 | C39: =_xlfn.XLOOKUP($A39,[1]usmn_pd!$A$2:$A$118,[1]usmn_pd!$D$2:$D$118,"n/a",0,1)/1000 -> 50.161761 | D39: -0.81204505 | F39: =_xlfn.XLOOKUP($A39,[1]usmn_pd!$A$2:$A$118,[1]usmn_pd!$F$2:$F$118,"N/A",0,1) -> 3.3487413 | G39: =F39-($F$26-$F$105)/($C$26*1000-$C$105*1000)*($C39*1000-$C$105*1000)-$F$105 -> -3.9707924 | H39: =G39+($D$26-$D$105)/($C$26*1000-$C$105*1000)*($C39*1000-$C$105*1000)+$D$105 -> -3.9780958 | I39: =$D39-VLOOKUP($A39,[1]usmn_pd!$A$2:$F$118,6,FALSE) -> -4.1607863 | J39: =$Q$2*$C39^3+$P$2*$C39^2+$O$2*$C39+$N$2 -> -4.1894995 | K39: =(I39-J39)^2 -> 0.00082444556 | L39: =K39/J39 -> -0.00019678856
A40: pd_c7d | B40: =VLOOKUP(A40,[2]usmn_ana14_pd!$A$2:$B$119,2,FALSE) -> 222.91542 | C40: =_xlfn.XLOOKUP($A40,[1]usmn_pd!$A$2:$A$118,[1]usmn_pd!$D$2:$D$118,"n/a",0,1)/1000 -> 41.445857 | D40: -0.67198669 | F40: =_xlfn.XLOOKUP($A40,[1]usmn_pd!$A$2:$A$118,[1]usmn_pd!$F$2:$F$118,"N/A",0,1) -> 2.7508357 | G40: =F40-($F$26-$F$105)/($C$26*1000-$C$105*1000)*($C40*1000-$C$105*1000)-$F$105 -> -4.3898319 | H40: =G40+($D$26-$D$105)/($C$26*1000-$C$105*1000)*($C40*1000-$C$105*1000)+$D$105 -> -4.3942903 | I40: =$D40-VLOOKUP($A40,[1]usmn_pd!$A$2:$F$118,6,FALSE) -> -3.4228224 | J40: =$Q$2*$C40^3+$P$2*$C40^2+$O$2*$C40+$N$2 -> -3.6470063 | K40: =(I40-J40)^2 -> 0.050258412 | L40: =K40/J40 -> -0.013780731
A41: pd_c8u | B41: =VLOOKUP(A41,[2]usmn_ana14_pd!$A$2:$B$119,2,FALSE) -> 228.20102 | C41: =_xlfn.XLOOKUP($A41,[1]usmn_pd!$A$2:$A$118,[1]usmn_pd!$D$2:$D$118,"n/a",0,1)/1000 -> 36.160219 | D41: -1.0751789 | F41: =_xlfn.XLOOKUP($A41,[1]usmn_pd!$A$2:$A$118,[1]usmn_pd!$F$2:$F$118,"N/A",0,1) -> 2.1111619 | G41: =F41-($F$26-$F$105)/($C$26*1000-$C$105*1000)*($C41*1000-$C$105*1000)-$F$105 -> -4.921035 | H41: =G41+($D$26-$D$105)/($C$26*1000-$C$105*1000)*($C41*1000-$C$105*1000)+$D$105 -> -4.9237681 | I41: =$D41-VLOOKUP($A41,[1]usmn_pd!$A$2:$F$118,6,FALSE) -> -3.1863408 | J41: =$Q$2*$C41^3+$P$2*$C41^2+$O$2*$C41+$N$2 -> -3.3310461 | K41: =(I41-J41)^2 -> 0.020939618 | L41: =K41/J41 -> -0.0062861989
... A105: pd_57d | B105: =VLOOKUP(A105,[2]usmn_ana14_pd!$A$2:$B$119,2,FALSE) -> 630.4051 | C105: =_xlfn.XLOOKUP($A105,[1]usmn_pd!$A$2:$A$118,[1]usmn_pd!$D$2:$D$118,"n/a",0,1)/1000 -> -366.04374 | D105: 0.12855249 | F105: =_xlfn.XLOOKUP($A105,[1]usmn_pd!$A$2:$A$118,[1]usmn_pd!$F$2:$F$118,"N/A",0,1) -> -1.2217502 | G105: =F105-($F$26-$F$105)/($C$26*1000-$C$105*1000)*($C105*1000-$C$105*1000)-$F$105 -> 0 | H105: =G105+($D$26-$D$105)/($C$26*1000-$C$105*1000)*($C105*1000-$C$105*1000)+$D$105 -> 0.12855249 | I105: =$D105-VLOOKUP($A105,[1]usmn_pd!$A$2:$F$118,6,FALSE) -> 1.3503027 | J105: =$Q$2*$C105^3+$P$2*$C105^2+$O$2*$C105+$N$2 -> 1.1172484 | K105: =(I105-J105)^2 -> 0.054314276 | L105: =K105/J105 -> 0.048614323
C107: 124.105 | J107: =$Q$2*$C107^3+$P$2*$C107^2+$O$2*$C107+$N$2 -> -9.940671
C108: =C107-1 -> 123.105 | J108: =$Q$2*$C108^3+$P$2*$C108^2+$O$2*$C108+$N$2 -> -9.8483744
C109: =C108-1 -> 122.105 | J109: =$Q$2*$C109^3+$P$2*$C109^2+$O$2*$C109+$N$2 -> -9.7564953
C110: =C109-1 -> 121.105 | J110: =$Q$2*$C110^3+$P$2*$C110^2+$O$2*$C110+$N$2 -> -9.6650331
C111: =C110-1 -> 120.105 | J111: =$Q$2*$C111^3+$P$2*$C111^2+$O$2*$C111+$N$2 -> -9.5739868
C112: =C111-1 -> 119.105 | J112: =$Q$2*$C112^3+$P$2*$C112^2+$O$2*$C112+$N$2 -> -9.4833557
C113: =C112-1 -> 118.105 | J113: =$Q$2*$C113^3+$P$2*$C113^2+$O$2*$C113+$N$2 -> -9.3931389
...

Sheet survey_data
A1: Point Name | B1: x [mm] | C1: y [mm] | D1: z [mm] | E1: Ux [mm] | F1: Uy [mm] | G1: Uz [mm]
A2: a16_12g | B2: -15476.493 | C2: -14406.92 | D2: -596.67609 | E2: 0.19341636 | F2: 0.02168505 | G2: 0.03294449
A3: a16_14g | B3: -15476.334 | C3: -15445.313 | D3: -596.24402 | E3: 0.19620559 | F3: 0.01928458 | G3: 0.03107999
A4: a16_15g | B4: -15476.286 | C4: -15969.994 | D4: -596.40084 | E4: 0.19560848 | F4: 0.01770398 | G4: 0.02979327
A5: a16_21g | B5: -15476.188 | C5: -16507.223 | D5: -596.48096 | E5: 0.1943626 | F5: 0.01736329 | G5: 0.02939205
A6: a16_22g | B6: -15476.16 | C6: -17007.198 | D6: -596.50776 | E6: 0.19538823 | F6: 0.01696465 | G6: 0.02797511
A7: a16_24g | B7: -15476.051 | C7: -18044.941 | D7: -596.18784 | E7: 0.19496094 | F7: 0.01713386 | G7: 0.02864317
A8: a16_25g | B8: -15475.903 | C8: -18570.061 | D8: -596.47657 | E8: 0.19731869 | F8: 0.01833388 | G8: 0.02798386
A9: a16_31g | B9: -15475.893 | C9: -19107.335 | D9: -596.38323 | E9: 0.19634192 | F9: 0.01928613 | G9: 0.0287664
A10: a16_32g | B10: -15475.81 | C10: -19606.908 | D10: -596.45465 | E10: 0.19725374 | F10: 0.02012663 | G10: 0.02793912
A11: a16_34g | B11: -15475.699 | C11: -20632.051 | D11: -596.28949 | E11: 0.1971772 | F11: 0.02315026 | G11: 0.03253108
A12: a16_35g | B12: -15475.674 | C12: -21182.557 | D12: -596.53514 | E12: 0.19716859 | F12: 0.02255079 | G12: 0.03070053
A13: a16_41g | B13: -15475.588 | C13: -21694.808 | D13: -597.10424 | E13: 0.19798699 | F13: 0.02196232 | G13: 0.03263612
... A833: sl_16_35d | B833: -14996.445 | C833: -21197.253 | D833: 50.27695 | E833: 0.19734692 | F833: 0.02242646 | G833: 0.0300967

Sheet lattice
A1: regend :
C2: a : acceleration tubes | D2: d : designed or calculated | E2: a : active flag
C3: f : fiducial points | D3: s : surveyed
C4: m : magnets
C5: d : diagnostics
C6: v : vacuum components
C7: g : gun
C8: s : solenoid
C9: sa : solenoid on acceleration tube
A12: beam_source | B12: segment_name | C12: inst_type | D12: d/s | F12: point_name | G12: element_name | H12: element_type | I12: s [m] | J12: xd [mm] | K12: yd [mm] | L12: zd [mm] | M12: xs [mm] | N12: ys [mm] | O12: zs [mm] | P12: zs' [mm] | Q12: Δx [mm] | R12: Δy [mm] | S12: Δz [mm] | T12: Δz' [mm] | U12: x' [rad] | V12: y' [rad] | W12: z' [rad] | X12: drift [mm] | Y12: element_length [mm] | Z12: center-to-center_length [mm] | AA12: effective_length [m] | AB12: bore_dia [mm] | AC12: aperture [mm] | AD12: Remarks
A13: AS | B13: A | C13: g | D13: d | E13: a | F13: gr_as | G13: gr_as | I13: =_xlfn.XLOOKUP($F13,設計座標!$E$13:$E$2301,設計座標!$G$13:$G$2301,"n/a",0,1) -> -4.3755336 | J13: =_xlfn.XLOOKUP($F13,設計座標!$E$13:$E$2301,設計座標!$H$13:$H$2301,"n/a",0,1) -> -3513.6945 | K13: =_xlfn.XLOOKUP($F13,設計座標!$E$13:$E$2301,設計座標!$I$13:$I$2301,"n/a",0,1) -> -9209.3249 | L13: =_xlfn.XLOOKUP($F13,設計座標!$E$13:$E$2301,設計座標!$J$13:$J$2301,"n/a",0,1) -> -270 | M13: =J13 -> -3513.6945 | N13: =K13 -> -9209.3249 | O13: =L13 -> -270 | P13: =$L13+$T13 -> -269.06959 | Q13: =$M13-$J13 -> 0 | R13: =$N13-$K13 -> 0 | S13: =$O13-$L13 -> 0 | T13: =$S13+測地線補正!$Q$3*(lattice!$N13/1000)^3+測地線補正!$P$3*(lattice!$N13/1000)^2+測地線補正!$O$3*(lattice!$N13/1000)+測地線補正!$N$3 -> 0.9304078 | U13: 0 | V13: 0 | W13: 0 | X13: 0 | Y13: =_xlfn.XLOOKUP($F13,設計座標!$E$13:$E$2301,設計座標!$L$13:$L$2301," ",0,1) -> 0 | Z13: 0
A14: AS | B14: A | C14: s | D14: d | E14: a | F14: sx_as_1c | G14: sx_as_1 | I14: =_xlfn.XLOOKUP($F14,設計座標!$E$13:$E$2301,設計座標!$G$13:$G$2301,"n/a",0,1) -> -3.8115152 | J14: =_xlfn.XLOOKUP($F14,設計座標!$E$13:$E$2301,設計座標!$H$13:$H$2301,"n/a",0,1) -> -2949.6761 | K14: =_xlfn.XLOOKUP($F14,設計座標!$E$13:$E$2301,設計座標!$I$13:$I$2301,"n/a",0,1) -> -9209.3249 | L14: =_xlfn.XLOOKUP($F14,設計座標!$E$13:$E$2301,設計座標!$J$13:$J$2301,"n/a",0,1) -> -160 | M14: =J14 -> -2949.6761 | N14: =K14 -> -9209.3249 | O14: =L14 -> -160 | P14: =$L14+$T14 -> -159.06959 | Q14: =$M14-$J14 -> 0 | R14: =$N14-$K14 -> 0 | S14: =$O14-$L14 -> 0 | T14: =$S14+測地線補正!$Q$3*(lattice!$N14/1000)^3+測地線補正!$P$3*(lattice!$N14/1000)^2+測地線補正!$O$3*(lattice!$N14/1000)+測地線補正!$N$3 -> 0.9304078 | U14: 0 | V14: 0 | W14: 0 | X14: =$Z$14-($Y$14+$Y$13)/2 -> 560.0184 | Y14: =_xlfn.XLOOKUP($F14,設計座標!$E$13:$E$2301,設計座標!$L$13:$L$2301," ",0,1) -> 68 | Z14: 594.0184 | AA14: =_xlfn.XLOOKUP($G14,magnet_list!$A$2:$A$592,magnet_list!$AJ$2:$AJ$592,"n/a",0,1) -> 0.080397 | AB14: =_xlfn.XLOOKUP($G14,magnet_list!$A$2:$A$592,magnet_list!$L$2:$L$592,"n/a",0,1) -> 80
A15: AS | B15: A | C15: s | D15: d | E15: a | F15: sy_as_1c | G15: sy_as_1 | I15: =_xlfn.XLOOKUP($F15,設計座標!$E$13:$E$2301,設計座標!$G$13:$G$2301,"n/a",0,1) -> -3.8115152 | J15: =_xlfn.XLOOKUP($F15,設計座標!$E$13:$E$2301,設計座標!$H$13:$H$2301,"n/a",0,1) -> -2949.6761 | K15: =_xlfn.XLOOKUP($F15,設計座標!$E$13:$E$2301,設計座標!$I$13:$I$2301,"n/a",0,1) -> -9209.3249 | L15: =_xlfn.XLOOKUP($F15,設計座標!$E$13:$E$2301,設計座標!$J$13:$J$2301,"n/a",0,1) -> -160 | M15: =J15 -> -2949.6761 | N15: =K15 -> -9209.3249 | O15: =L15 -> -160 | P15: =$L15+$T15 -> -159.06959 | Q15: =$M15-$J15 -> 0 | R15: =$N15-$K15 -> 0 | S15: =$O15-$L15 -> 0 | T15: =$S15+測地線補正!$Q$3*(lattice!$N15/1000)^3+測地線補正!$P$3*(lattice!$N15/1000)^2+測地線補正!$O$3*(lattice!$N15/1000)+測地線補正!$N$3 -> 0.9304078 | U15: 0 | V15: 0 | W15: 0 | X15: =$Z$14-($Y$14+$Y$13)/2 -> 560.0184 | Y15: =_xlfn.XLOOKUP($F15,設計座標!$E$13:$E$2301,設計座標!$L$13:$L$2301," ",0,1) -> 68 | Z15: 594.0184 | AA15: =_xlfn.XLOOKUP($G15,magnet_list!$A$2:$A$592,magnet_list!$AJ$2:$AJ$592,"n/a",0,1) -> 0.080397 | AB15: =_xlfn.XLOOKUP($G15,magnet_list!$A$2:$A$592,magnet_list!$L$2:$L$592,"n/a",0,1) -> 80
A16: AS | B16: A | C16: d | D16: d | E16: a | F16: sc_as_0 | G16: sc_as_0 | I16: =_xlfn.XLOOKUP($F16,設計座標!$E$13:$E$2301,設計座標!$G$13:$G$2301,"n/a",0,1) -> -3.4624152 | J16: =_xlfn.XLOOKUP($F16,設計座標!$E$13:$E$2301,設計座標!$H$13:$H$2301,"n/a",0,1) -> -2600.5761 | K16: =_xlfn.XLOOKUP($F16,設計座標!$E$13:$E$2301,設計座標!$I$13:$I$2301,"n/a",0,1) -> -9209.3249 | L16: =_xlfn.XLOOKUP($F16,設計座標!$E$13:$E$2301,設計座標!$J$13:$J$2301,"n/a",0,1) -> -270 | M16: =J16 -> -2600.5761 | N16: =K16 -> -9209.3249 | O16: =L16 -> -270 | P16: =$L16+$T16 -> -269.06959 | Q16: =$M16-$J16 -> 0 | R16: =$N16-$K16 -> 0 | S16: =$O16-$L16 -> 0 | T16: =$S16+測地線補正!$Q$3*(lattice!$N16/1000)^3+測地線補正!$P$3*(lattice!$N16/1000)^2+測地線補正!$O$3*(lattice!$N16/1000)+測地線補正!$N$3 -> 0.9304078 | U16: 0 | V16: 0 | W16: 0 | X16: =$Z$16-($Y$16+$Y$15)/2 -> 315.1 | Y16: =_xlfn.XLOOKUP($F16,設計座標!$E$13:$E$2301,設計座標!$L$13:$L$2301," ",0,1) -> 0 | Z16: =SQRT(($M$16-$M$15)^2+($N$16-$N$15)^2) -> 349.1
A17: AS | B17: A | C17: d | D17: d | E17: a | F17: sp_as_1 | G17: sp_as_1 | I17: =_xlfn.XLOOKUP($F17,設計座標!$E$13:$E$2301,設計座標!$G$13:$G$2301,"n/a",0,1) -> -3.3559152 | J17: =_xlfn.XLOOKUP($F17,設計座標!$E$13:$E$2301,設計座標!$H$13:$H$2301,"n/a",0,1) -> -2494.0761 | K17: =_xlfn.XLOOKUP($F17,設計座標!$E$13:$E$2301,設計座標!$I$13:$I$2301,"n/a",0,1) -> -9209.3249 | L17: =_xlfn.XLOOKUP($F17,設計座標!$E$13:$E$2301,設計座標!$J$13:$J$2301,"n/a",0,1) -> -270 | M17: =J17 -> -2494.0761 | N17: =K17 -> -9209.3249 | O17: =L17 -> -270 | P17: =$L17+$T17 -> -269.06959 | Q17: =$M17-$J17 -> 0 | R17: =$N17-$K17 -> 0 | S17: =$O17-$L17 -> 0 | T17: =$S17+測地線補正!$Q$3*(lattice!$N17/1000)^3+測地線補正!$P$3*(lattice!$N17/1000)^2+測地線補正!$O$3*(lattice!$N17/1000)+測地線補正!$N$3 -> 0.9304078 | U17: 0 | V17: 0 | W17: 0 | X17: =$Z$17-($Y$17+$Y$16)/2 -> 106.5 | Y17: =_xlfn.XLOOKUP($F17,設計座標!$E$13:$E$2301,設計座標!$L$13:$L$2301," ",0,1) -> 0 | Z17: =SQRT(($M$17-$M$16)^2+($N$17-$N$16)^2) -> 106.5
A18: AS | B18: A | C18: m | D18: d | E18: a | F18: qf_as_1c | G18: qf_as_1 | I18: =_xlfn.XLOOKUP($F18,設計座標!$E$13:$E$2301,設計座標!$G$13:$G$2301,"n/a",0,1) -> -3.2999152 | J18: =_xlfn.XLOOKUP($F18,設計座標!$E$13:$E$2301,設計座標!$H$13:$H$2301,"n/a",0,1) -> -2438.0761 | K18: =_xlfn.XLOOKUP($F18,設計座標!$E$13:$E$2301,設計座標!$I$13:$I$2301,"n/a",0,1) -> -9209.3249 | L18: =_xlfn.XLOOKUP($F18,設計座標!$E$13:$E$2301,設計座標!$J$13:$J$2301,"n/a",0,1) -> -125 | M18: =J18 -> -2438.0761 | N18: =K18 -> -9209.3249 | O18: =L18 -> -125 | P18: =$L18+$T18 -> -124.06959 | Q18: =$M18-$J18 -> 0 | R18: =$N18-$K18 -> 0 | S18: =$O18-$L18 -> 0 | T18: =$S18+測地線補正!$Q$3*(lattice!$N18/1000)^3+測地線補正!$P$3*(lattice!$N18/1000)^2+測地線補正!$O$3*(lattice!$N18/1000)+測地線補正!$N$3 -> 0.9304078 | U18: 0 | V18: 0 | W18: 0 | X18: =$Z$18-($Y$18+$Y$17)/2 -> 31 | Y18: =_xlfn.XLOOKUP($F18,設計座標!$E$13:$E$2301,設計座標!$L$13:$L$2301," ",0,1) -> 50 | Z18: =SQRT(($M$18-$M$17)^2+($N$18-$N$17)^2) -> 56 | AA18: =_xlfn.XLOOKUP($G18,magnet_list!$A$2:$A$592,magnet_list!$AJ$2:$AJ$592,"n/a",0,1) -> 0.074785 | AB18: =_xlfn.XLOOKUP($G18,magnet_list!$A$2:$A$592,magnet_list!$L$2:$L$592,"n/a",0,1) -> 44
A19: AS | B19: A | C19: m | D19: d | E19: a | F19: qd_as_1c | G19: qd_as_1 | I19: =_xlfn.XLOOKUP($F19,設計座標!$E$13:$E$2301,設計座標!$G$13:$G$2301,"n/a",0,1) -> -3.1499152 | J19: =_xlfn.XLOOKUP($F19,設計座標!$E$13:$E$2301,設計座標!$H$13:$H$2301,"n/a",0,1) -> -2288.0761 | K19: =_xlfn.XLOOKUP($F19,設計座標!$E$13:$E$2301,設計座標!$I$13:$I$2301,"n/a",0,1) -> -9209.3249 | L19: =_xlfn.XLOOKUP($F19,設計座標!$E$13:$E$2301,設計座標!$J$13:$J$2301,"n/a",0,1) -> -125 | M19: =J19 -> -2288.0761 | N19: =K19 -> -9209.3249 | O19: =L19 -> -125 | P19: =$L19+$T19 -> -124.06959 | Q19: =$M19-$J19 -> 0 | R19: =$N19-$K19 -> 0 | S19: =$O19-$L19 -> 0 | T19: =$S19+測地線補正!$Q$3*(lattice!$N19/1000)^3+測地線補正!$P$3*(lattice!$N19/1000)^2+測地線補正!$O$3*(lattice!$N19/1000)+測地線補正!$N$3 -> 0.9304078 | U19: 0 | V19: 0 | W19: 0 | X19: =$Z$19-($Y$19+$Y$18)/2 -> 100 | Y19: =_xlfn.XLOOKUP($F19,設計座標!$E$13:$E$2301,設計座標!$L$13:$L$2301," ",0,1) -> 50 | Z19: =SQRT(($M$19-$M$18)^2+($N$19-$N$18)^2) -> 150 | AA19: =_xlfn.XLOOKUP($G19,magnet_list!$A$2:$A$592,magnet_list!$AJ$2:$AJ$592,"n/a",0,1) -> 0.074785 | AB19: =_xlfn.XLOOKUP($G19,magnet_list!$A$2:$A$592,magnet_list!$L$2:$L$592,"n/a",0,1) -> 44
A20: AS | B20: A | C20: s | D20: d | E20: a | F20: sx_as_2c | G20: sx_as_2 | I20: =_xlfn.XLOOKUP($F20,設計座標!$E$13:$E$2301,設計座標!$G$13:$G$2301,"n/a",0,1) -> -2.9909152 | J20: =_xlfn.XLOOKUP($F20,設計座標!$E$13:$E$2301,設計座標!$H$13:$H$2301,"n/a",0,1) -> -2129.0761 | K20: =_xlfn.XLOOKUP($F20,設計座標!$E$13:$E$2301,設計座標!$I$13:$I$2301,"n/a",0,1) -> -9209.3249 | L20: =_xlfn.XLOOKUP($F20,設計座標!$E$13:$E$2301,設計座標!$J$13:$J$2301,"n/a",0,1) -> -160 | M20: =J20 -> -2129.0761 | N20: =K20 -> -9209.3249 | O20: =L20 -> -160 | P20: =$L20+$T20 -> -159.06959 | Q20: =$M20-$J20 -> 0 | R20: =$N20-$K20 -> 0 | S20: =$O20-$L20 -> 0 | T20: =$S20+測地線補正!$Q$3*(lattice!$N20/1000)^3+測地線補正!$P$3*(lattice!$N20/1000)^2+測地線補正!$O$3*(lattice!$N20/1000)+測地線補正!$N$3 -> 0.9304078 | U20: 0 | V20: 0 | W20: 0 | X20: =$Z$20-($Y$20+$Y$19)/2 -> 100 | Y20: =_xlfn.XLOOKUP($F20,設計座標!$E$13:$E$2301,設計座標!$L$13:$L$2301," ",0,1) -> 68 | Z20: =SQRT(($M$20-$M$19)^2+($N$20-$N$19)^2) -> 159 | AA20: =_xlfn.XLOOKUP($G20,magnet_list!$A$2:$A$592,magnet_list!$AJ$2:$AJ$592,"n/a",0,1) -> 0.080397 | AB20: =_xlfn.XLOOKUP($G20,magnet_list!$A$2:$A$592,magnet_list!$L$2:$L$592,"n/a",0,1) -> 80
A21: AS | B21: A | C21: s | D21: d | E21: a | F21: sy_as_2c | G21: sy_as_2 | I21: =_xlfn.XLOOKUP($F21,設計座標!$E$13:$E$2301,設計座標!$G$13:$G$2301,"n/a",0,1) -> -2.9909152 | J21: =_xlfn.XLOOKUP($F21,設計座標!$E$13:$E$2301,設計座標!$H$13:$H$2301,"n/a",0,1) -> -2129.0761 | K21: =_xlfn.XLOOKUP($F21,設計座標!$E$13:$E$2301,設計座標!$I$13:$I$2301,"n/a",0,1) -> -9209.3249 | L21: =_xlfn.XLOOKUP($F21,設計座標!$E$13:$E$2301,設計座標!$J$13:$J$2301,"n/a",0,1) -> -160 | M21: =J21 -> -2129.0761 | N21: =K21 -> -9209.3249 | O21: =L21 -> -160 | P21: =$L21+$T21 -> -159.06959 | Q21: =$M21-$J21 -> 0 | R21: =$N21-$K21 -> 0 | S21: =$O21-$L21 -> 0 | T21: =$S21+測地線補正!$Q$3*(lattice!$N21/1000)^3+測地線補正!$P$3*(lattice!$N21/1000)^2+測地線補正!$O$3*(lattice!$N21/1000)+測地線補正!$N$3 -> 0.9304078 | U21: 0 | V21: 0 | W21: 0 | X21: =$Z$21-($Y$21+$Y$20)/2 -> 91 | Y21: =_xlfn.XLOOKUP($F21,設計座標!$E$13:$E$2301,設計座標!$L$13:$L$2301," ",0,1) -> 68 | Z21: =SQRT(($M$21-$M$19)^2+($N$21-$N$19)^2) -> 159 | AA21: =_xlfn.XLOOKUP($G21,magnet_list!$A$2:$A$592,magnet_list!$AJ$2:$AJ$592,"n/a",0,1) -> 0.080397 | AB21: =_xlfn.XLOOKUP($G21,magnet_list!$A$2:$A$592,magnet_list!$L$2:$L$592,"n/a",0,1) -> 80
A22: AS | B22: A | C22: m | D22: d | E22: a | F22: bm_as_1c | G22: bm_as_1 | I22: =_xlfn.XLOOKUP($F22,設計座標!$E$13:$E$2301,設計座標!$G$13:$G$2301,"n/a",0,1) -> -2.5606722 | J22: =_xlfn.XLOOKUP($F22,設計座標!$E$13:$E$2301,設計座標!$H$13:$H$2301,"n/a",0,1) -> -1703.8409 | K22: =_xlfn.XLOOKUP($F22,設計座標!$E$13:$E$2301,設計座標!$I$13:$I$2301,"n/a",0,1) -> -9171.2647 | L22: =_xlfn.XLOOKUP($F22,設計座標!$E$13:$E$2301,設計座標!$J$13:$J$2301,"n/a",0,1) -> -125 | M22: =J22 -> -1703.8409 | N22: =K22 -> -9171.2647 | O22: =L22 -> -125 | P22: =$L22+$T22 -> -124.07355 | Q22: =$M22-$J22 -> 0 | R22: =$N22-$K22 -> 0 | S22: =$O22-$L22 -> 0 | T22: =$S22+測地線補正!$Q$3*(lattice!$N22/1000)^3+測地線補正!$P$3*(lattice!$N22/1000)^2+測地線補正!$O$3*(lattice!$N22/1000)+測地線補正!$N$3 -> 0.92644915 | U22: 0 | V22: 0 | W22: 0 | X22: =$Z$22-($Y$22+$Y$21)/2 -> 358.8928 | Y22: =_xlfn.XLOOKUP($F22,設計座標!$E$13:$E$2301,設計座標!$L$13:$L$2301," ",0,1) -> 392.7005 | Z22: =392.8928+392.7005/2 -> 589.24305 | AA22: =_xlfn.XLOOKUP($G22,magnet_list!$A$2:$A$592,magnet_list!$AJ$2:$AJ$592,"n/a",0,1) -> 0.4229 | AB22: =_xlfn.XLOOKUP($G22,magnet_list!$A$2:$A$592,magnet_list!$L$2:$L$592,"n/a",0,1) -> 30 | AD22: arc length = 392.7005
A23: AT | B23: A | C23: d | D23: d | E23: a | F23: sp_at_0 | G23: sp_at_0 | I23: =_xlfn.XLOOKUP($F23,設計座標!$E$13:$E$2301,設計座標!$G$13:$G$2301,"n/a",0,1) -> -2.6197772 | J23: =_xlfn.XLOOKUP($F23,設計座標!$E$13:$E$2301,設計座標!$H$13:$H$2301,"n/a",0,1) -> 0 | K23: =_xlfn.XLOOKUP($F23,設計座標!$E$13:$E$2301,設計座標!$I$13:$I$2301,"n/a",0,1) -> -9862.4183 | L23: =_xlfn.XLOOKUP($F23,設計座標!$E$13:$E$2301,設計座標!$J$13:$J$2301,"n/a",0,1) -> 480 | M23: =$J23+$Q23 -> 0.17967065 | N23: =K23 -> -9862.4183 | O23: =$L23+$S23 -> 477.32357 | P23: =$L23+$T23 -> 478.32222 | Q23: =(Q$28-Q$25)/($N$28-$N$25)*($N23-$N$25)+Q$25 -> 0.17967065 | R23: =$N23-$K23 -> 0 | S23: =(S$28-S$25)/($N$28-$N$25)*($N23-$N$25)+S$25 -> -2.6764294 | T23: =$S23+測地線補正!$Q$3*(lattice!$N23/1000)^3+測地線補正!$P$3*(lattice!$N23/1000)^2+測地線補正!$O$3*(lattice!$N23/1000)+測地線補正!$N$3 -> -1.6777826 | U23: 0 | V23: 0 | W23: 0 | X23: 0 | Y23: =_xlfn.XLOOKUP($F23,設計座標!$E$13:$E$2301,設計座標!$L$13:$L$2301," ",0,1) -> 0 | Z23: 0
A24: AT | B24: A | C24: m | D24: d | E24: a | F24: qd_at_01c | G24: qd_at_01 | I24: =_xlfn.XLOOKUP($F24,設計座標!$E$13:$E$2301,設計座標!$G$13:$G$2301,"n/a",0,1) -> -2.5382772 | J24: =_xlfn.XLOOKUP($F24,設計座標!$E$13:$E$2301,設計座標!$H$13:$H$2301,"n/a",0,1) -> 0 | K24: =_xlfn.XLOOKUP($F24,設計座標!$E$13:$E$2301,設計座標!$I$13:$I$2301,"n/a",0,1) -> -9780.9183 | L24: =_xlfn.XLOOKUP($F24,設計座標!$E$13:$E$2301,設計座標!$J$13:$J$2301,"n/a",0,1) -> 642 | M24: =$J24+$Q24 -> 0.17025481 | N24: =K24 -> -9780.9183 | O24: =$L24+$S24 -> 639.31588 | P24: =$L24+$T24 -> 640.30598 | Q24: =(Q$28-Q$25)/($N$28-$N$25)*($N24-$N$25)+Q$25 -> 0.17025481 | R24: =$N24-$K24 -> 0 | S24: =(S$28-S$25)/($N$28-$N$25)*($N24-$N$25)+S$25 -> -2.6841229 | T24: =$S24+測地線補正!$Q$3*(lattice!$N24/1000)^3+測地線補正!$P$3*(lattice!$N24/1000)^2+測地線補正!$O$3*(lattice!$N24/1000)+測地線補正!$N$3 -> -1.6940239 | U24: 0 | V24: 0 | W24: 0 | X24: =$Z$24-($Y$24+$Y$23)/2 -> 56.500001 | Y24: =_xlfn.XLOOKUP($F24,設計座標!$E$13:$E$2301,設計座標!$L$13:$L$2301," ",0,1) -> 50 | Z24: =SQRT(($M$24-$M$23)^2+($N$24-$N$23)^2) -> 81.500001 | AA24: =_xlfn.XLOOKUP($G24,magnet_list!$A$2:$A$592,magnet_list!$AJ$2:$AJ$592,"n/a",0,1) -> 0.0725 | AB24: =_xlfn.XLOOKUP($G24,magnet_list!$A$2:$A$592,magnet_list!$L$2:$L$592,"n/a",0,1) -> 44
A25: AT | B25: A | C25: m | D25: s | F25: qf_at_02 | G25: qf_at_02 | I25: =_xlfn.XLOOKUP($F25,設計座標!$E$13:$E$2301,設計座標!$G$13:$G$2301,"n/a",0,1) -> -2.3932772 | J25: =_xlfn.XLOOKUP($F25,設計座標!$E$13:$E$2301,設計座標!$H$13:$H$2301,"n/a",0,1) -> 0 | K25: =_xlfn.XLOOKUP($F25,設計座標!$E$13:$E$2301,設計座標!$I$13:$I$2301,"n/a",0,1) -> -9635.9183 | L25: =_xlfn.XLOOKUP($F25,設計座標!$E$13:$E$2301,設計座標!$J$13:$J$2301,"n/a",0,1) -> 642 | M25: =_xlfn.XLOOKUP($F25,survey_data!$A$2:$A$833,survey_data!$B$2:$B$833,"n/a",0,1) -> 0.15350271 | N25: =_xlfn.XLOOKUP($F25,survey_data!$A$2:$A$833,survey_data!$C$2:$C$833,"n/a",0,1) -> -9635.9183 | O25: =_xlfn.XLOOKUP($F25,survey_data!$A$2:$A$833,survey_data!$D$2:$D$833,"n/a",0,1) -> 639.30219 | P25: =$L25+$T25 -> 640.2771 | Q25: =$M25-$J25 -> 0.15350271 | R25: =$N25-$K25 -> 0 | S25: =$O25-$L25 -> -2.6978108 | T25: =$S25+測地線補正!$Q$3*(lattice!$N25/1000)^3+測地線補正!$P$3*(lattice!$N25/1000)^2+測地線補正!$O$3*(lattice!$N25/1000)+測地線補正!$N$3 -> -1.7228968 | U25: =ATAN(($P$26-$P$25)/ABS($N$26-$N$25)) -> -0.00019900216 | V25: 0 | W25: =-ATAN(($M$26-$M$25)/ABS($N$26-$N$25)) -> 0.00011553174 | X25: =$Z$26-($Y$26+$Y$24)/2 -> 100.00007 | Y25: =_xlfn.XLOOKUP($F25,設計座標!$E$13:$E$2301,設計座標!$L$13:$L$2301," ",0,1) -> 100 | Z25: =SQRT(($M$26-$M$24)^2+($N$26-$N$24)^2) -> 175.00007 | AA25: =_xlfn.XLOOKUP($G25,magnet_list!$A$2:$A$592,magnet_list!$AJ$2:$AJ$592,"n/a",0,1) -> 0.122 | AB25: =_xlfn.XLOOKUP($G25,magnet_list!$A$2:$A$592,magnet_list!$L$2:$L$592,"n/a",0,1) -> 44
A26: AT | B26: A | C26: m | D26: d | E26: a | F26: qf_at_02c | G26: qf_at_02 | I26: =_xlfn.XLOOKUP($F26,設計座標!$E$13:$E$2301,設計座標!$G$13:$G$2301,"n/a",0,1) -> -2.3632771 | J26: =_xlfn.XLOOKUP($F26,設計座標!$E$13:$E$2301,設計座標!$H$13:$H$2301,"n/a",0,1) -> 0 | K26: =_xlfn.XLOOKUP($F26,設計座標!$E$13:$E$2301,設計座標!$I$13:$I$2301,"n/a",0,1) -> -9605.9182 | L26: =_xlfn.XLOOKUP($F26,設計座標!$E$13:$E$2301,設計座標!$J$13:$J$2301,"n/a",0,1) -> 642 | M26: =$J26+$Q26 -> 0.15003675 | N26: =K26 -> -9605.9182 | O26: =$L26+$S26 -> 639.29936 | P26: =$L26+$T26 -> 640.27113 | Q26: =(Q$28-Q$25)/($N$28-$N$25)*($N26-$N$25)+Q$25 -> 0.15003675 | R26: =$N26-$K26 -> 0 | S26: =(S$28-S$25)/($N$28-$N$25)*($N26-$N$25)+S$25 -> -2.7006428 | T26: =$S26+測地線補正!$Q$3*(lattice!$N26/1000)^3+測地線補正!$P$3*(lattice!$N26/1000)^2+測地線補正!$O$3*(lattice!$N26/1000)+測地線補正!$N$3 -> -1.7288668 | U26: =ATAN(($P$26-$P$25)/ABS($N$26-$N$25)) -> -0.00019900216 | V26: 0 | W26: =-ATAN(($M$26-$M$25)/ABS($N$26-$N$25)) -> 0.00011553174 | X26: =$Z$26-($Y$26+$Y$24)/2 -> 100.00007 | Y26: =_xlfn.XLOOKUP($F26,設計座標!$E$13:$E$2301,設計座標!$L$13:$L$2301," ",0,1) -> 100 | Z26: =SQRT(($M$26-$M$24)^2+($N$26-$N$24)^2) -> 175.00007 | AA26: =_xlfn.XLOOKUP($G26,magnet_list!$A$2:$A$592,magnet_list!$AJ$2:$AJ$592,"n/a",0,1) -> 0.122 | AB26: =_xlfn.XLOOKUP($G26,magnet_list!$A$2:$A$592,magnet_list!$L$2:$L$592,"n/a",0,1) -> 44
